Workbook

Sheet Info
A1: Mid-Project Jarkom K2 – Subnetting Smart City Kota Surabaya
A2: Sumber kebutuhan host: soal UTS Komdat Jarkom, 23 Oktober 2026. Sel kuning berteks biru = input; sel lain berisi rumus.
A3: Parameter | B3: Nilai
A4: Nomor kelompok (K) | B4: 2
A5: Oktet ke-2 (8 × K) | B5: =8*B4 -> 16
A6: Base network | B6: ="10."&B5&".0.0" -> 10.16.0.0
A7: Skema yang dipasang di Packet Tracer | B7: CIDR
A8: Link R-PUSAT – R-ISP | B8: ="203.0.113."&(4*B4)&"/30" -> 203.0.113.8/30
A9: Server internet | B9: 8.8.8.8/24, gateway 8.8.8.1 di R-ISP
A10: Tunnel GRE | B10: ="192.168."&B4&".0/30 (R-PUSAT .1, R-PELABUHAN .2)" -> 192.168.2.0/30 (R-PUSAT .1, R-PELABUHAN .2)
A11: Domain internal | B11: ="k"&B4&".smartcity.lab" -> k2.smartcity.lab
A14: Anggota
A15: Nama | B15: NRP
A16: Dian Piramidiana Rachmatika | B16: 5027251031
A17: Muhammad Rifqi Fathurrahman | B17: 5027251029
A18: Ronnin Raditya Putra Partono | B18: 5027251119
A20: Aturan perhitungan
A21: • Kebutuhan LAN = host + 1 gateway + 2 (network & broadcast). Link antar-router = 2 host + 2 = 4 (/30), tanpa gateway.
A22: • Gateway setiap LAN = host pertama. Di setiap link /30, router atas memakai host pertama, router bawah host kedua.
A23: • Offset = posisi alamat relatif terhadap base: (oktet2 − base) × 65536 + oktet3 × 256 + oktet4.
A24: • VLSM: offset berurutan dari subnet terbesar. CIDR: offset diambil dari pohon penggabungan (sheet Supernet).
A25: • Kolom Cek: 'OK' berarti network habis dibagi ukuran blok (aligned) dan tidak tumpang tindih dengan baris sebelumnya.
A26: • Link ISP, server 8.8.8.8, dan tunnel GRE tidak ikut dihitung (sudah diberikan soal).
A27: • Alasan memilih 10.0.0.0/8: rentang privat terbesar (16,7 juta alamat); kebutuhan CIDR mencapai 262.144 alamat sehingga 192.168.0.0/16 tidak cukup, dan aturan oktet ke-2 = 8 × K hanya leluasa di blok 10.x.

Sheet Kebutuhan
A1: Tabel Kebutuhan (Soal UTS 1b)
A2: Host = input dari soal UTS. Kebutuhan, blok, prefix, dan mask dihitung otomatis.
A4: No | B4: Router | C4: Subnet | D4: Jenis | E4: Host | F4: Kebutuhan | G4: Ukuran blok | H4: Prefix | I4: Subnet mask
A5: 1 | B5: R-PUSAT | C5: Pegawai Balai Kota | D5: LAN | E5: 1800 | F5: =IF(D5="Link",E5+2,E5+3) -> 1803 | G5: =2^CEILING(ROUND(LOG(F5,2),9),1) -> 2048 | H5: =32-ROUND(LOG(G5,2),0) -> 21 | I5: =(256-2^(8-MIN(8,MAX(0,H5-0))))&"."&(256-2^(8-MIN(8,MAX(0,H5-8))))&"."&(256-2^(8-MIN(8,MAX(0,H5-16))))&"."&(256-2^(8-MIN(8,MAX(0,H5-24)))) -> 255.255.248.0
A6: 2 | B6: R-PUSAT | C6: Server Balai Kota | D6: LAN | E6: 20 | F6: =IF(D6="Link",E6+2,E6+3) -> 23 | G6: =2^CEILING(ROUND(LOG(F6,2),9),1) -> 32 | H6: =32-ROUND(LOG(G6,2),0) -> 27 | I6: =(256-2^(8-MIN(8,MAX(0,H6-0))))&"."&(256-2^(8-MIN(8,MAX(0,H6-8))))&"."&(256-2^(8-MIN(8,MAX(0,H6-16))))&"."&(256-2^(8-MIN(8,MAX(0,H6-24)))) -> 255.255.255.224
A7: 3 | B7: R-DC | C7: CCTV Kota | D7: LAN | E7: 6000 | F7: =IF(D7="Link",E7+2,E7+3) -> 6003 | G7: =2^CEILING(ROUND(LOG(F7,2),9),1) -> 8192 | H7: =32-ROUND(LOG(G7,2),0) -> 19 | I7: =(256-2^(8-MIN(8,MAX(0,H7-0))))&"."&(256-2^(8-MIN(8,MAX(0,H7-8))))&"."&(256-2^(8-MIN(8,MAX(0,H7-16))))&"."&(256-2^(8-MIN(8,MAX(0,H7-24)))) -> 255.255.224.0
A8: 4 | B8: R-DC | C8: Server dan Storage DC | D8: LAN | E8: 180 | F8: =IF(D8="Link",E8+2,E8+3) -> 183 | G8: =2^CEILING(ROUND(LOG(F8,2),9),1) -> 256 | H8: =32-ROUND(LOG(G8,2),0) -> 24 | I8: =(256-2^(8-MIN(8,MAX(0,H8-0))))&"."&(256-2^(8-MIN(8,MAX(0,H8-8))))&"."&(256-2^(8-MIN(8,MAX(0,H8-16))))&"."&(256-2^(8-MIN(8,MAX(0,H8-24)))) -> 255.255.255.0
A9: 5 | B9: R-UTARA | C9: WiFi Publik Utara | D9: LAN | E9: 11000 | F9: =IF(D9="Link",E9+2,E9+3) -> 11003 | G9: =2^CEILING(ROUND(LOG(F9,2),9),1) -> 16384 | H9: =32-ROUND(LOG(G9,2),0) -> 18 | I9: =(256-2^(8-MIN(8,MAX(0,H9-0))))&"."&(256-2^(8-MIN(8,MAX(0,H9-8))))&"."&(256-2^(8-MIN(8,MAX(0,H9-16))))&"."&(256-2^(8-MIN(8,MAX(0,H9-24)))) -> 255.255.192.0
A10: 6 | B10: R-UTARA | C10: Sensor Lalu Lintas Utara | D10: LAN | E10: 450 | F10: =IF(D10="Link",E10+2,E10+3) -> 453 | G10: =2^CEILING(ROUND(LOG(F10,2),9),1) -> 512 | H10: =32-ROUND(LOG(G10,2),0) -> 23 | I10: =(256-2^(8-MIN(8,MAX(0,H10-0))))&"."&(256-2^(8-MIN(8,MAX(0,H10-8))))&"."&(256-2^(8-MIN(8,MAX(0,H10-16))))&"."&(256-2^(8-MIN(8,MAX(0,H10-24)))) -> 255.255.254.0
A11: 7 | B11: R-PELABUHAN | C11: Sensor dan SCADA Pelabuhan | D11: LAN | E11: 5000 | F11: =IF(D11="Link",E11+2,E11+3) -> 5003 | G11: =2^CEILING(ROUND(LOG(F11,2),9),1) -> 8192 | H11: =32-ROUND(LOG(G11,2),0) -> 19 | I11: =(256-2^(8-MIN(8,MAX(0,H11-0))))&"."&(256-2^(8-MIN(8,MAX(0,H11-8))))&"."&(256-2^(8-MIN(8,MAX(0,H11-16))))&"."&(256-2^(8-MIN(8,MAX(0,H11-24)))) -> 255.255.224.0
A12: 8 | B12: R-PELABUHAN | C12: Kantor Pelabuhan | D12: LAN | E12: 120 | F12: =IF(D12="Link",E12+2,E12+3) -> 123 | G12: =2^CEILING(ROUND(LOG(F12,2),9),1) -> 128 | H12: =32-ROUND(LOG(G12,2),0) -> 25 | I12: =(256-2^(8-MIN(8,MAX(0,H12-0))))&"."&(256-2^(8-MIN(8,MAX(0,H12-8))))&"."&(256-2^(8-MIN(8,MAX(0,H12-16))))&"."&(256-2^(8-MIN(8,MAX(0,H12-24)))) -> 255.255.255.128
A13: 9 | B13: R-SELATAN | C13: WiFi Publik Selatan | D13: LAN | E13: 6500 | F13: =IF(D13="Link",E13+2,E13+3) -> 6503 | G13: =2^CEILING(ROUND(LOG(F13,2),9),1) -> 8192 | H13: =32-ROUND(LOG(G13,2),0) -> 19 | I13: =(256-2^(8-MIN(8,MAX(0,H13-0))))&"."&(256-2^(8-MIN(8,MAX(0,H13-8))))&"."&(256-2^(8-MIN(8,MAX(0,H13-16))))&"."&(256-2^(8-MIN(8,MAX(0,H13-24)))) -> 255.255.224.0
A14: 10 | B14: R-SELATAN | C14: PJU Pintar Selatan | D14: LAN | E14: 90 | F14: =IF(D14="Link",E14+2,E14+3) -> 93 | G14: =2^CEILING(ROUND(LOG(F14,2),9),1) -> 128 | H14: =32-ROUND(LOG(G14,2),0) -> 25 | I14: =(256-2^(8-MIN(8,MAX(0,H14-0))))&"."&(256-2^(8-MIN(8,MAX(0,H14-8))))&"."&(256-2^(8-MIN(8,MAX(0,H14-16))))&"."&(256-2^(8-MIN(8,MAX(0,H14-24)))) -> 255.255.255.128
A15: 11 | B15: R-TIMUR | C15: WiFi Publik Timur | D15: LAN | E15: 5500 | F15: =IF(D15="Link",E15+2,E15+3) -> 5503 | G15: =2^CEILING(ROUND(LOG(F15,2),9),1) -> 8192 | H15: =32-ROUND(LOG(G15,2),0) -> 19 | I15: =(256-2^(8-MIN(8,MAX(0,H15-0))))&"."&(256-2^(8-MIN(8,MAX(0,H15-8))))&"."&(256-2^(8-MIN(8,MAX(0,H15-16))))&"."&(256-2^(8-MIN(8,MAX(0,H15-24)))) -> 255.255.224.0
A16: 12 | B16: R-TIMUR | C16: Sensor Banjir Timur | D16: LAN | E16: 700 | F16: =IF(D16="Link",E16+2,E16+3) -> 703 | G16: =2^CEILING(ROUND(LOG(F16,2),9),1) -> 1024 | H16: =32-ROUND(LOG(G16,2),0) -> 22 | I16: =(256-2^(8-MIN(8,MAX(0,H16-0))))&"."&(256-2^(8-MIN(8,MAX(0,H16-8))))&"."&(256-2^(8-MIN(8,MAX(0,H16-16))))&"."&(256-2^(8-MIN(8,MAX(0,H16-24)))) -> 255.255.252.0
... A24: 20 | B24: R-UTARA – R-PELABUHAN | C24: L6 UTARA-PELABUHAN | D24: Link | E24: 2 | F24: =IF(D24="Link",E24+2,E24+3) -> 4 | G24: =2^CEILING(ROUND(LOG(F24,2),9),1) -> 4 | H24: =32-ROUND(LOG(G24,2),0) -> 30 | I24: =(256-2^(8-MIN(8,MAX(0,H24-0))))&"."&(256-2^(8-MIN(8,MAX(0,H24-8))))&"."&(256-2^(8-MIN(8,MAX(0,H24-16))))&"."&(256-2^(8-MIN(8,MAX(0,H24-24)))) -> 255.255.255.252
C25: Total | E25: =SUM(E5:E24) -> 42092 | F25: =SUM(F5:F24) -> 42146 | G25: =SUM(G5:G24) -> 61752

Sheet VLSM
A1: Tabel VLSM (perbaikan dari lembar UTS)
A2: Urutan dari blok terbesar; offset berurutan (rumus). Perbaikan terhadap jawaban UTS dicatat di sheet Revisi.
J3: Kolom bantu hitung
A4: No | B4: Nama subnet | C4: Router / sisi | D4: Network ID | E4: Prefix | F4: Subnet mask | G4: Rentang host | H4: Broadcast | I4: Gateway | J4: Host | K4: Ukuran blok | L4: Offset | M4: Cek aligned | N4: Cek urut
A5: 1 | B5: WiFi Publik Utara | C5: =INDEX(Kebutuhan!$B$5:$B$24,MATCH($B5,Kebutuhan!$C$5:$C$24,0)) -> R-UTARA | D5: ="10."&(Info!$B$5+INT((L5)/65536))&"."&INT(MOD((L5),65536)/256)&"."&MOD((L5),256) -> 10.16.0.0 | E5: ="/"&INDEX(Kebutuhan!$H$5:$H$24,MATCH($B5,Kebutuhan!$C$5:$C$24,0)) -> /18 | F5: =INDEX(Kebutuhan!$I$5:$I$24,MATCH($B5,Kebutuhan!$C$5:$C$24,0)) -> 255.255.192.0 | G5: ="10."&(Info!$B$5+INT((L5+1)/65536))&"."&INT(MOD((L5+1),65536)/256)&"."&MOD((L5+1),256)&" – "&"10."&(Info!$B$5+INT((L5+K5-2)/65536))&"."&INT(MOD((L5+K5-2),65536)/256)&"."&MOD((L5+K5-2),256) -> 10.16.0.1 – 10.16.63.254 | H5: ="10."&(Info!$B$5+INT((L5+K5-1)/65536))&"."&INT(MOD((L5+K5-1),65536)/256)&"."&MOD((L5+K5-1),256) -> 10.16.63.255 | I5: =IF(INDEX(Kebutuhan!$D$5:$D$24,MATCH($B5,Kebutuhan!$C$5:$C$24,0))="Link","—","10."&(Info!$B$5+INT((L5+1)/65536))&"."&INT(MOD((L5+1),65536)/256)&"."&MOD((L5+1),256)) -> 10.16.0.1 | J5: =INDEX(Kebutuhan!$E$5:$E$24,MATCH($B5,Kebutuhan!$C$5:$C$24,0)) -> 11000 | K5: =INDEX(Kebutuhan!$G$5:$G$24,MATCH($B5,Kebutuhan!$C$5:$C$24,0)) -> 16384 | L5: 0 | M5: =IF(MOD(L5,K5)=0,"OK","TIDAK ALIGNED") -> OK | N5: OK
A6: 2 | B6: WiFi Publik Selatan | C6: =INDEX(Kebutuhan!$B$5:$B$24,MATCH($B6,Kebutuhan!$C$5:$C$24,0)) -> R-SELATAN | D6: ="10."&(Info!$B$5+INT((L6)/65536))&"."&INT(MOD((L6),65536)/256)&"."&MOD((L6),256) -> 10.16.64.0 | E6: ="/"&INDEX(Kebutuhan!$H$5:$H$24,MATCH($B6,Kebutuhan!$C$5:$C$24,0)) -> /19 | F6: =INDEX(Kebutuhan!$I$5:$I$24,MATCH($B6,Kebutuhan!$C$5:$C$24,0)) -> 255.255.224.0 | G6: ="10."&(Info!$B$5+INT((L6+1)/65536))&"."&INT(MOD((L6+1),65536)/256)&"."&MOD((L6+1),256)&" – "&"10."&(Info!$B$5+INT((L6+K6-2)/65536))&"."&INT(MOD((L6+K6-2),65536)/256)&"."&MOD((L6+K6-2),256) -> 10.16.64.1 – 10.16.95.254 | H6: ="10."&(Info!$B$5+INT((L6+K6-1)/65536))&"."&INT(MOD((L6+K6-1),65536)/256)&"."&MOD((L6+K6-1),256) -> 10.16.95.255 | I6: =IF(INDEX(Kebutuhan!$D$5:$D$24,MATCH($B6,Kebutuhan!$C$5:$C$24,0))="Link","—","10."&(Info!$B$5+INT((L6+1)/65536))&"."&INT(MOD((L6+1),65536)/256)&"."&MOD((L6+1),256)) -> 10.16.64.1 | J6: =INDEX(Kebutuhan!$E$5:$E$24,MATCH($B6,Kebutuhan!$C$5:$C$24,0)) -> 6500 | K6: =INDEX(Kebutuhan!$G$5:$G$24,MATCH($B6,Kebutuhan!$C$5:$C$24,0)) -> 8192 | L6: =L5+K5 -> 16384 | M6: =IF(MOD(L6,K6)=0,"OK","TIDAK ALIGNED") -> OK | N6: =IF(L6>=L5+K5,"OK","OVERLAP") -> OK
A7: 3 | B7: CCTV Kota | C7: =INDEX(Kebutuhan!$B$5:$B$24,MATCH($B7,Kebutuhan!$C$5:$C$24,0)) -> R-DC | D7: ="10."&(Info!$B$5+INT((L7)/65536))&"."&INT(MOD((L7),65536)/256)&"."&MOD((L7),256) -> 10.16.96.0 | E7: ="/"&INDEX(Kebutuhan!$H$5:$H$24,MATCH($B7,Kebutuhan!$C$5:$C$24,0)) -> /19 | F7: =INDEX(Kebutuhan!$I$5:$I$24,MATCH($B7,Kebutuhan!$C$5:$C$24,0)) -> 255.255.224.0 | G7: ="10."&(Info!$B$5+INT((L7+1)/65536))&"."&INT(MOD((L7+1),65536)/256)&"."&MOD((L7+1),256)&" – "&"10."&(Info!$B$5+INT((L7+K7-2)/65536))&"."&INT(MOD((L7+K7-2),65536)/256)&"."&MOD((L7+K7-2),256) -> 10.16.96.1 – 10.16.127.254 | H7: ="10."&(Info!$B$5+INT((L7+K7-1)/65536))&"."&INT(MOD((L7+K7-1),65536)/256)&"."&MOD((L7+K7-1),256) -> 10.16.127.255 | I7: =IF(INDEX(Kebutuhan!$D$5:$D$24,MATCH($B7,Kebutuhan!$C$5:$C$24,0))="Link","—","10."&(Info!$B$5+INT((L7+1)/65536))&"."&INT(MOD((L7+1),65536)/256)&"."&MOD((L7+1),256)) -> 10.16.96.1 | J7: =INDEX(Kebutuhan!$E$5:$E$24,MATCH($B7,Kebutuhan!$C$5:$C$24,0)) -> 6000 | K7: =INDEX(Kebutuhan!$G$5:$G$24,MATCH($B7,Kebutuhan!$C$5:$C$24,0)) -> 8192 | L7: =L6+K6 -> 24576 | M7: =IF(MOD(L7,K7)=0,"OK","TIDAK ALIGNED") -> OK | N7: =IF(L7>=L6+K6,"OK","OVERLAP") -> OK
A8: 4 | B8: WiFi Publik Timur | C8: =INDEX(Kebutuhan!$B$5:$B$24,MATCH($B8,Kebutuhan!$C$5:$C$24,0)) -> R-TIMUR | D8: ="10."&(Info!$B$5+INT((L8)/65536))&"."&INT(MOD((L8),65536)/256)&"."&MOD((L8),256) -> 10.16.128.0 | E8: ="/"&INDEX(Kebutuhan!$H$5:$H$24,MATCH($B8,Kebutuhan!$C$5:$C$24,0)) -> /19 | F8: =INDEX(Kebutuhan!$I$5:$I$24,MATCH($B8,Kebutuhan!$C$5:$C$24,0)) -> 255.255.224.0 | G8: ="10."&(Info!$B$5+INT((L8+1)/65536))&"."&INT(MOD((L8+1),65536)/256)&"."&MOD((L8+1),256)&" – "&"10."&(Info!$B$5+INT((L8+K8-2)/65536))&"."&INT(MOD((L8+K8-2),65536)/256)&"."&MOD((L8+K8-2),256) -> 10.16.128.1 – 10.16.159.254 | H8: ="10."&(Info!$B$5+INT((L8+K8-1)/65536))&"."&INT(MOD((L8+K8-1),65536)/256)&"."&MOD((L8+K8-1),256) -> 10.16.159.255 | I8: =IF(INDEX(Kebutuhan!$D$5:$D$24,MATCH($B8,Kebutuhan!$C$5:$C$24,0))="Link","—","10."&(Info!$B$5+INT((L8+1)/65536))&"."&INT(MOD((L8+1),65536)/256)&"."&MOD((L8+1),256)) -> 10.16.128.1 | J8: =INDEX(Kebutuhan!$E$5:$E$24,MATCH($B8,Kebutuhan!$C$5:$C$24,0)) -> 5500 | K8: =INDEX(Kebutuhan!$G$5:$G$24,MATCH($B8,Kebutuhan!$C$5:$C$24,0)) -> 8192 | L8: =L7+K7 -> 32768 | M8: =IF(MOD(L8,K8)=0,"OK","TIDAK ALIGNED") -> OK | N8: =IF(L8>=L7+K7,"OK","OVERLAP") -> OK
A9: 5 | B9: Sensor dan SCADA Pelabuhan | C9: =INDEX(Kebutuhan!$B$5:$B$24,MATCH($B9,Kebutuhan!$C$5:$C$24,0)) -> R-PELABUHAN | D9: ="10."&(Info!$B$5+INT((L9)/65536))&"."&INT(MOD((L9),65536)/256)&"."&MOD((L9),256) -> 10.16.160.0 | E9: ="/"&INDEX(Kebutuhan!$H$5:$H$24,MATCH($B9,Kebutuhan!$C$5:$C$24,0)) -> /19 | F9: =INDEX(Kebutuhan!$I$5:$I$24,MATCH($B9,Kebutuhan!$C$5:$C$24,0)) -> 255.255.224.0 | G9: ="10."&(Info!$B$5+INT((L9+1)/65536))&"."&INT(MOD((L9+1),65536)/256)&"."&MOD((L9+1),256)&" – "&"10."&(Info!$B$5+INT((L9+K9-2)/65536))&"."&INT(MOD((L9+K9-2),65536)/256)&"."&MOD((L9+K9-2),256) -> 10.16.160.1 – 10.16.191.254 | H9: ="10."&(Info!$B$5+INT((L9+K9-1)/65536))&"."&INT(MOD((L9+K9-1),65536)/256)&"."&MOD((L9+K9-1),256) -> 10.16.191.255 | I9: =IF(INDEX(Kebutuhan!$D$5:$D$24,MATCH($B9,Kebutuhan!$C$5:$C$24,0))="Link","—","10."&(Info!$B$5+INT((L9+1)/65536))&"."&INT(MOD((L9+1),65536)/256)&"."&MOD((L9+1),256)) -> 10.16.160.1 | J9: =INDEX(Kebutuhan!$E$5:$E$24,MATCH($B9,Kebutuhan!$C$5:$C$24,0)) -> 5000 | K9: =INDEX(Kebutuhan!$G$5:$G$24,MATCH($B9,Kebutuhan!$C$5:$C$24,0)) -> 8192 | L9: =L8+K8 -> 40960 | M9: =IF(MOD(L9,K9)=0,"OK","TIDAK ALIGNED") -> OK | N9: =IF(L9>=L8+K8,"OK","OVERLAP") -> OK
A10: 6 | B10: WiFi Publik Barat | C10: =INDEX(Kebutuhan!$B$5:$B$24,MATCH($B10,Kebutuhan!$C$5:$C$24,0)) -> R-BARAT | D10: ="10."&(Info!$B$5+INT((L10)/65536))&"."&INT(MOD((L10),65536)/256)&"."&MOD((L10),256) -> 10.16.192.0 | E10: ="/"&INDEX(Kebutuhan!$H$5:$H$24,MATCH($B10,Kebutuhan!$C$5:$C$24,0)) -> /19 | F10: =INDEX(Kebutuhan!$I$5:$I$24,MATCH($B10,Kebutuhan!$C$5:$C$24,0)) -> 255.255.224.0 | G10: ="10."&(Info!$B$5+INT((L10+1)/65536))&"."&INT(MOD((L10+1),65536)/256)&"."&MOD((L10+1),256)&" – "&"10."&(Info!$B$5+INT((L10+K10-2)/65536))&"."&INT(MOD((L10+K10-2),65536)/256)&"."&MOD((L10+K10-2),256) -> 10.16.192.1 – 10.16.223.254 | H10: ="10."&(Info!$B$5+INT((L10+K10-1)/65536))&"."&INT(MOD((L10+K10-1),65536)/256)&"."&MOD((L10+K10-1),256) -> 10.16.223.255 | I10: =IF(INDEX(Kebutuhan!$D$5:$D$24,MATCH($B10,Kebutuhan!$C$5:$C$24,0))="Link","—","10."&(Info!$B$5+INT((L10+1)/65536))&"."&INT(MOD((L10+1),65536)/256)&"."&MOD((L10+1),256)) -> 10.16.192.1 | J10: =INDEX(Kebutuhan!$E$5:$E$24,MATCH($B10,Kebutuhan!$C$5:$C$24,0)) -> 4500 | K10: =INDEX(Kebutuhan!$G$5:$G$24,MATCH($B10,Kebutuhan!$C$5:$C$24,0)) -> 8192 | L10: =L9+K9 -> 49152 | M10: =IF(MOD(L10,K10)=0,"OK","TIDAK ALIGNED") -> OK | N10: =IF(L10>=L9+K9,"OK","OVERLAP") -> OK
A11: 7 | B11: Pegawai Balai Kota | C11: =INDEX(Kebutuhan!$B$5:$B$24,MATCH($B11,Kebutuhan!$C$5:$C$24,0)) -> R-PUSAT | D11: ="10."&(Info!$B$5+INT((L11)/65536))&"."&INT(MOD((L11),65536)/256)&"."&MOD((L11),256) -> 10.16.224.0 | E11: ="/"&INDEX(Kebutuhan!$H$5:$H$24,MATCH($B11,Kebutuhan!$C$5:$C$24,0)) -> /21 | F11: =INDEX(Kebutuhan!$I$5:$I$24,MATCH($B11,Kebutuhan!$C$5:$C$24,0)) -> 255.255.248.0 | G11: ="10."&(Info!$B$5+INT((L11+1)/65536))&"."&INT(MOD((L11+1),65536)/256)&"."&MOD((L11+1),256)&" – "&"10."&(Info!$B$5+INT((L11+K11-2)/65536))&"."&INT(MOD((L11+K11-2),65536)/256)&"."&MOD((L11+K11-2),256) -> 10.16.224.1 – 10.16.231.254 | H11: ="10."&(Info!$B$5+INT((L11+K11-1)/65536))&"."&INT(MOD((L11+K11-1),65536)/256)&"."&MOD((L11+K11-1),256) -> 10.16.231.255 | I11: =IF(INDEX(Kebutuhan!$D$5:$D$24,MATCH($B11,Kebutuhan!$C$5:$C$24,0))="Link","—","10."&(Info!$B$5+INT((L11+1)/65536))&"."&INT(MOD((L11+1),65536)/256)&"."&MOD((L11+1),256)) -> 10.16.224.1 | J11: =INDEX(Kebutuhan!$E$5:$E$24,MATCH($B11,Kebutuhan!$C$5:$C$24,0)) -> 1800 | K11: =INDEX(Kebutuhan!$G$5:$G$24,MATCH($B11,Kebutuhan!$C$5:$C$24,0)) -> 2048 | L11: =L10+K10 -> 57344 | M11: =IF(MOD(L11,K11)=0,"OK","TIDAK ALIGNED") -> OK | N11: =IF(L11>=L10+K10,"OK","OVERLAP") -> OK
A12: 8 | B12: Sensor Banjir Timur | C12: =INDEX(Kebutuhan!$B$5:$B$24,MATCH($B12,Kebutuhan!$C$5:$C$24,0)) -> R-TIMUR | D12: ="10."&(Info!$B$5+INT((L12)/65536))&"."&INT(MOD((L12),65536)/256)&"."&MOD((L12),256) -> 10.16.232.0 | E12: ="/"&INDEX(Kebutuhan!$H$5:$H$24,MATCH($B12,Kebutuhan!$C$5:$C$24,0)) -> /22 | F12: =INDEX(Kebutuhan!$I$5:$I$24,MATCH($B12,Kebutuhan!$C$5:$C$24,0)) -> 255.255.252.0 | G12: ="10."&(Info!$B$5+INT((L12+1)/65536))&"."&INT(MOD((L12+1),65536)/256)&"."&MOD((L12+1),256)&" – "&"10."&(Info!$B$5+INT((L12+K12-2)/65536))&"."&INT(MOD((L12+K12-2),65536)/256)&"."&MOD((L12+K12-2),256) -> 10.16.232.1 – 10.16.235.254 | H12: ="10."&(Info!$B$5+INT((L12+K12-1)/65536))&"."&INT(MOD((L12+K12-1),65536)/256)&"."&MOD((L12+K12-1),256) -> 10.16.235.255 | I12: =IF(INDEX(Kebutuhan!$D$5:$D$24,MATCH($B12,Kebutuhan!$C$5:$C$24,0))="Link","—","10."&(Info!$B$5+INT((L12+1)/65536))&"."&INT(MOD((L12+1),65536)/256)&"."&MOD((L12+1),256)) -> 10.16.232.1 | J12: =INDEX(Kebutuhan!$E$5:$E$24,MATCH($B12,Kebutuhan!$C$5:$C$24,0)) -> 700 | K12: =INDEX(Kebutuhan!$G$5:$G$24,MATCH($B12,Kebutuhan!$C$5:$C$24,0)) -> 1024 | L12: =L11+K11 -> 59392 | M12: =IF(MOD(L12,K12)=0,"OK","TIDAK ALIGNED") -> OK | N12: =IF(L12>=L11+K11,"OK","OVERLAP") -> OK
A13: 9 | B13: Sensor Lalu Lintas Utara | C13: =INDEX(Kebutuhan!$B$5:$B$24,MATCH($B13,Kebutuhan!$C$5:$C$24,0)) -> R-UTARA | D13: ="10."&(Info!$B$5+INT((L13)/65536))&"."&INT(MOD((L13),65536)/256)&"."&MOD((L13),256) -> 10.16.236.0 | E13: ="/"&INDEX(Kebutuhan!$H$5:$H$24,MATCH($B13,Kebutuhan!$C$5:$C$24,0)) -> /23 | F13: =INDEX(Kebutuhan!$I$5:$I$24,MATCH($B13,Kebutuhan!$C$5:$C$24,0)) -> 255.255.254.0 | G13: ="10."&(Info!$B$5+INT((L13+1)/65536))&"."&INT(MOD((L13+1),65536)/256)&"."&MOD((L13+1),256)&" – "&"10."&(Info!$B$5+INT((L13+K13-2)/65536))&"."&INT(MOD((L13+K13-2),65536)/256)&"."&MOD((L13+K13-2),256) -> 10.16.236.1 – 10.16.237.254 | H13: ="10."&(Info!$B$5+INT((L13+K13-1)/65536))&"."&INT(MOD((L13+K13-1),65536)/256)&"."&MOD((L13+K13-1),256) -> 10.16.237.255 | I13: =IF(INDEX(Kebutuhan!$D$5:$D$24,MATCH($B13,Kebutuhan!$C$5:$C$24,0))="Link","—","10."&(Info!$B$5+INT((L13+1)/65536))&"."&INT(MOD((L13+1),65536)/256)&"."&MOD((L13+1),256)) -> 10.16.236.1 | J13: =INDEX(Kebutuhan!$E$5:$E$24,MATCH($B13,Kebutuhan!$C$5:$C$24,0)) -> 450 | K13: =INDEX(Kebutuhan!$G$5:$G$24,MATCH($B13,Kebutuhan!$C$5:$C$24,0)) -> 512 | L13: =L12+K12 -> 60416 | M13: =IF(MOD(L13,K13)=0,"OK","TIDAK ALIGNED") -> OK | N13: =IF(L13>=L12+K12,"OK","OVERLAP") -> OK
A14: 10 | B14: Puskesmas dan Sekolah Barat | C14: =INDEX(Kebutuhan!$B$5:$B$24,MATCH($B14,Kebutuhan!$C$5:$C$24,0)) -> R-BARAT | D14: ="10."&(Info!$B$5+INT((L14)/65536))&"."&INT(MOD((L14),65536)/256)&"."&MOD((L14),256) -> 10.16.238.0 | E14: ="/"&INDEX(Kebutuhan!$H$5:$H$24,MATCH($B14,Kebutuhan!$C$5:$C$24,0)) -> /24 | F14: =INDEX(Kebutuhan!$I$5:$I$24,MATCH($B14,Kebutuhan!$C$5:$C$24,0)) -> 255.255.255.0 | G14: ="10."&(Info!$B$5+INT((L14+1)/65536))&"."&INT(MOD((L14+1),65536)/256)&"."&MOD((L14+1),256)&" – "&"10."&(Info!$B$5+INT((L14+K14-2)/65536))&"."&INT(MOD((L14+K14-2),65536)/256)&"."&MOD((L14+K14-2),256) -> 10.16.238.1 – 10.16.238.254 | H14: ="10."&(Info!$B$5+INT((L14+K14-1)/65536))&"."&INT(MOD((L14+K14-1),65536)/256)&"."&MOD((L14+K14-1),256) -> 10.16.238.255 | I14: =IF(INDEX(Kebutuhan!$D$5:$D$24,MATCH($B14,Kebutuhan!$C$5:$C$24,0))="Link","—","10."&(Info!$B$5+INT((L14+1)/65536))&"."&INT(MOD((L14+1),65536)/256)&"."&MOD((L14+1),256)) -> 10.16.238.1 | J14: =INDEX(Kebutuhan!$E$5:$E$24,MATCH($B14,Kebutuhan!$C$5:$C$24,0)) -> 220 | K14: =INDEX(Kebutuhan!$G$5:$G$24,MATCH($B14,Kebutuhan!$C$5:$C$24,0)) -> 256 | L14: =L13+K13 -> 60928 | M14: =IF(MOD(L14,K14)=0,"OK","TIDAK ALIGNED") -> OK | N14: =IF(L14>=L13+K13,"OK","OVERLAP") -> OK
A15: 11 | B15: Server dan Storage DC | C15: =INDEX(Kebutuhan!$B$5:$B$24,MATCH($B15,Kebutuhan!$C$5:$C$24,0)) -> R-DC | D15: ="10."&(Info!$B$5+INT((L15)/65536))&"."&INT(MOD((L15),65536)/256)&"."&MOD((L15),256) -> 10.16.239.0 | E15: ="/"&INDEX(Kebutuhan!$H$5:$H$24,MATCH($B15,Kebutuhan!$C$5:$C$24,0)) -> /24 | F15: =INDEX(Kebutuhan!$I$5:$I$24,MATCH($B15,Kebutuhan!$C$5:$C$24,0)) -> 255.255.255.0 | G15: ="10."&(Info!$B$5+INT((L15+1)/65536))&"."&INT(MOD((L15+1),65536)/256)&"."&MOD((L15+1),256)&" – "&"10."&(Info!$B$5+INT((L15+K15-2)/65536))&"."&INT(MOD((L15+K15-2),65536)/256)&"."&MOD((L15+K15-2),256) -> 10.16.239.1 – 10.16.239.254 | H15: ="10."&(Info!$B$5+INT((L15+K15-1)/65536))&"."&INT(MOD((L15+K15-1),65536)/256)&"."&MOD((L15+K15-1),256) -> 10.16.239.255 | I15: =IF(INDEX(Kebutuhan!$D$5:$D$24,MATCH($B15,Kebutuhan!$C$5:$C$24,0))="Link","—","10."&(Info!$B$5+INT((L15+1)/65536))&"."&INT(MOD((L15+1),65536)/256)&"."&MOD((L15+1),256)) -> 10.16.239.1 | J15: =INDEX(Kebutuhan!$E$5:$E$24,MATCH($B15,Kebutuhan!$C$5:$C$24,0)) -> 180 | K15: =INDEX(Kebutuhan!$G$5:$G$24,MATCH($B15,Kebutuhan!$C$5:$C$24,0)) -> 256 | L15: =L14+K14 -> 61184 | M15: =IF(MOD(L15,K15)=0,"OK","TIDAK ALIGNED") -> OK | N15: =IF(L15>=L14+K14,"OK","OVERLAP") -> OK
A16: 12 | B16: Kantor Pelabuhan | C16: =INDEX(Kebutuhan!$B$5:$B$24,MATCH($B16,Kebutuhan!$C$5:$C$24,0)) -> R-PELABUHAN | D16: ="10."&(Info!$B$5+INT((L16)/65536))&"."&INT(MOD((L16),65536)/256)&"."&MOD((L16),256) -> 10.16.240.0 | E16: ="/"&INDEX(Kebutuhan!$H$5:$H$24,MATCH($B16,Kebutuhan!$C$5:$C$24,0)) -> /25 | F16: =INDEX(Kebutuhan!$I$5:$I$24,MATCH($B16,Kebutuhan!$C$5:$C$24,0)) -> 255.255.255.128 | G16: ="10."&(Info!$B$5+INT((L16+1)/65536))&"."&INT(MOD((L16+1),65536)/256)&"."&MOD((L16+1),256)&" – "&"10."&(Info!$B$5+INT((L16+K16-2)/65536))&"."&INT(MOD((L16+K16-2),65536)/256)&"."&MOD((L16+K16-2),256) -> 10.16.240.1 – 10.16.240.126 | H16: ="10."&(Info!$B$5+INT((L16+K16-1)/65536))&"."&INT(MOD((L16+K16-1),65536)/256)&"."&MOD((L16+K16-1),256) -> 10.16.240.127 | I16: =IF(INDEX(Kebutuhan!$D$5:$D$24,MATCH($B16,Kebutuhan!$C$5:$C$24,0))="Link","—","10."&(Info!$B$5+INT((L16+1)/65536))&"."&INT(MOD((L16+1),65536)/256)&"."&MOD((L16+1),256)) -> 10.16.240.1 | J16: =INDEX(Kebutuhan!$E$5:$E$24,MATCH($B16,Kebutuhan!$C$5:$C$24,0)) -> 120 | K16: =INDEX(Kebutuhan!$G$5:$G$24,MATCH($B16,Kebutuhan!$C$5:$C$24,0)) -> 128 | L16: =L15+K15 -> 61440 | M16: =IF(MOD(L16,K16)=0,"OK","TIDAK ALIGNED") -> OK | N16: =IF(L16>=L15+K15,"OK","OVERLAP") -> OK
A17: 13 | B17: PJU Pintar Selatan | C17: =INDEX(Kebutuhan!$B$5:$B$24,MATCH($B17,Kebutuhan!$C$5:$C$24,0)) -> R-SELATAN | D17: ="10."&(Info!$B$5+INT((L17)/65536))&"."&INT(MOD((L17),65536)/256)&"."&MOD((L17),256) -> 10.16.240.128 | E17: ="/"&INDEX(Kebutuhan!$H$5:$H$24,MATCH($B17,Kebutuhan!$C$5:$C$24,0)) -> /25 | F17: =INDEX(Kebutuhan!$I$5:$I$24,MATCH($B17,Kebutuhan!$C$5:$C$24,0)) -> 255.255.255.128 | G17: ="10."&(Info!$B$5+INT((L17+1)/65536))&"."&INT(MOD((L17+1),65536)/256)&"."&MOD((L17+1),256)&" – "&"10."&(Info!$B$5+INT((L17+K17-2)/65536))&"."&INT(MOD((L17+K17-2),65536)/256)&"."&MOD((L17+K17-2),256) -> 10.16.240.129 – 10.16.240.254 | H17: ="10."&(Info!$B$5+INT((L17+K17-1)/65536))&"."&INT(MOD((L17+K17-1),65536)/256)&"."&MOD((L17+K17-1),256) -> 10.16.240.255 | I17: =IF(INDEX(Kebutuhan!$D$5:$D$24,MATCH($B17,Kebutuhan!$C$5:$C$24,0))="Link","—","10."&(Info!$B$5+INT((L17+1)/65536))&"."&INT(MOD((L17+1),65536)/256)&"."&MOD((L17+1),256)) -> 10.16.240.129 | J17: =INDEX(Kebutuhan!$E$5:$E$24,MATCH($B17,Kebutuhan!$C$5:$C$24,0)) -> 90 | K17: =INDEX(Kebutuhan!$G$5:$G$24,MATCH($B17,Kebutuhan!$C$5:$C$24,0)) -> 128 | L17: =L16+K16 -> 61568 | M17: =IF(MOD(L17,K17)=0,"OK","TIDAK ALIGNED") -> OK | N17: =IF(L17>=L16+K16,"OK","OVERLAP") -> OK
... A24: 20 | B24: L6 UTARA-PELABUHAN | C24: =INDEX(Kebutuhan!$B$5:$B$24,MATCH($B24,Kebutuhan!$C$5:$C$24,0)) -> R-UTARA – R-PELABUHAN | D24: ="10."&(Info!$B$5+INT((L24)/65536))&"."&INT(MOD((L24),65536)/256)&"."&MOD((L24),256) -> 10.16.241.52 | E24: ="/"&INDEX(Kebutuhan!$H$5:$H$24,MATCH($B24,Kebutuhan!$C$5:$C$24,0)) -> /30 | F24: =INDEX(Kebutuhan!$I$5:$I$24,MATCH($B24,Kebutuhan!$C$5:$C$24,0)) -> 255.255.255.252 | G24: ="10."&(Info!$B$5+INT((L24+1)/65536))&"."&INT(MOD((L24+1),65536)/256)&"."&MOD((L24+1),256)&" – "&"10."&(Info!$B$5+INT((L24+K24-2)/65536))&"."&INT(MOD((L24+K24-2),65536)/256)&"."&MOD((L24+K24-2),256) -> 10.16.241.53 – 10.16.241.54 | H24: ="10."&(Info!$B$5+INT((L24+K24-1)/65536))&"."&INT(MOD((L24+K24-1),65536)/256)&"."&MOD((L24+K24-1),256) -> 10.16.241.55 | I24: =IF(INDEX(Kebutuhan!$D$5:$D$24,MATCH($B24,Kebutuhan!$C$5:$C$24,0))="Link","—","10."&(Info!$B$5+INT((L24+1)/65536))&"."&INT(MOD((L24+1),65536)/256)&"."&MOD((L24+1),256)) -> — | J24: =INDEX(Kebutuhan!$E$5:$E$24,MATCH($B24,Kebutuhan!$C$5:$C$24,0)) -> 2 | K24: =INDEX(Kebutuhan!$G$5:$G$24,MATCH($B24,Kebutuhan!$C$5:$C$24,0)) -> 4 | L24: =L23+K23 -> 61748 | M24: =IF(MOD(L24,K24)=0,"OK","TIDAK ALIGNED") -> OK | N24: =IF(L24>=L23+K23,"OK","OVERLAP") -> OK
B26: Ringkasan | C26: Nilai
B27: Total ukuran blok | C27: =SUM(K5:K24) -> 61752
B28: Total host terpakai | C28: =SUM(J5:J24) -> 42092
B29: Prefix induk | C29: =32-CEILING(ROUND(LOG(C27,2),9),1) -> 16
B30: Ukuran blok induk | C30: =2^(32-C29) -> 65536
B31: Blok induk | C31: ="10."&Info!$B$5&".0.0/"&C29 -> 10.16.0.0/16

Sheet CIDR
A1: Tabel CIDR (diimplementasikan di Packet Tracer)
A2: Offset (kuning) diambil dari pohon penggabungan di sheet Supernet; network, range, broadcast, dan gateway dihitung otomatis.
J3: Kolom bantu hitung
A4: No | B4: Nama subnet | C4: Router / sisi | D4: Network ID | E4: Prefix | F4: Subnet mask | G4: Rentang host | H4: Broadcast | I4: Gateway | J4: Host | K4: Ukuran blok | L4: Offset | M4: Cek aligned | N4: Cek urut
A5: 1 | B5: CCTV Kota | C5: Sisi R-DC | D5: ="10."&(Info!$B$5+INT((L5)/65536))&"."&INT(MOD((L5),65536)/256)&"."&MOD((L5),256) -> 10.16.0.0 | E5: ="/"&INDEX(Kebutuhan!$H$5:$H$24,MATCH($B5,Kebutuhan!$C$5:$C$24,0)) -> /19 | F5: =INDEX(Kebutuhan!$I$5:$I$24,MATCH($B5,Kebutuhan!$C$5:$C$24,0)) -> 255.255.224.0 | G5: ="10."&(Info!$B$5+INT((L5+1)/65536))&"."&INT(MOD((L5+1),65536)/256)&"."&MOD((L5+1),256)&" – "&"10."&(Info!$B$5+INT((L5+K5-2)/65536))&"."&INT(MOD((L5+K5-2),65536)/256)&"."&MOD((L5+K5-2),256) -> 10.16.0.1 – 10.16.31.254 | H5: ="10."&(Info!$B$5+INT((L5+K5-1)/65536))&"."&INT(MOD((L5+K5-1),65536)/256)&"."&MOD((L5+K5-1),256) -> 10.16.31.255 | I5: =IF(INDEX(Kebutuhan!$D$5:$D$24,MATCH($B5,Kebutuhan!$C$5:$C$24,0))="Link","—","10."&(Info!$B$5+INT((L5+1)/65536))&"."&INT(MOD((L5+1),65536)/256)&"."&MOD((L5+1),256)) -> 10.16.0.1 | J5: =INDEX(Kebutuhan!$E$5:$E$24,MATCH($B5,Kebutuhan!$C$5:$C$24,0)) -> 6000 | K5: =INDEX(Kebutuhan!$G$5:$G$24,MATCH($B5,Kebutuhan!$C$5:$C$24,0)) -> 8192 | L5: 0 | M5: =IF(MOD(L5,K5)=0,"OK","TIDAK ALIGNED") -> OK | N5: OK
A6: 2 | B6: Server dan Storage DC | C6: Sisi R-DC | D6: ="10."&(Info!$B$5+INT((L6)/65536))&"."&INT(MOD((L6),65536)/256)&"."&MOD((L6),256) -> 10.16.32.0 | E6: ="/"&INDEX(Kebutuhan!$H$5:$H$24,MATCH($B6,Kebutuhan!$C$5:$C$24,0)) -> /24 | F6: =INDEX(Kebutuhan!$I$5:$I$24,MATCH($B6,Kebutuhan!$C$5:$C$24,0)) -> 255.255.255.0 | G6: ="10."&(Info!$B$5+INT((L6+1)/65536))&"."&INT(MOD((L6+1),65536)/256)&"."&MOD((L6+1),256)&" – "&"10."&(Info!$B$5+INT((L6+K6-2)/65536))&"."&INT(MOD((L6+K6-2),65536)/256)&"."&MOD((L6+K6-2),256) -> 10.16.32.1 – 10.16.32.254 | H6: ="10."&(Info!$B$5+INT((L6+K6-1)/65536))&"."&INT(MOD((L6+K6-1),65536)/256)&"."&MOD((L6+K6-1),256) -> 10.16.32.255 | I6: =IF(INDEX(Kebutuhan!$D$5:$D$24,MATCH($B6,Kebutuhan!$C$5:$C$24,0))="Link","—","10."&(Info!$B$5+INT((L6+1)/65536))&"."&INT(MOD((L6+1),65536)/256)&"."&MOD((L6+1),256)) -> 10.16.32.1 | J6: =INDEX(Kebutuhan!$E$5:$E$24,MATCH($B6,Kebutuhan!$C$5:$C$24,0)) -> 180 | K6: =INDEX(Kebutuhan!$G$5:$G$24,MATCH($B6,Kebutuhan!$C$5:$C$24,0)) -> 256 | L6: 8192 | M6: =IF(MOD(L6,K6)=0,"OK","TIDAK ALIGNED") -> OK | N6: =IF(L6>=L5+K5,"OK","OVERLAP") -> OK
A7: 3 | B7: L1 PUSAT-DC | C7: Sisi R-DC | D7: ="10."&(Info!$B$5+INT((L7)/65536))&"."&INT(MOD((L7),65536)/256)&"."&MOD((L7),256) -> 10.16.33.0 | E7: ="/"&INDEX(Kebutuhan!$H$5:$H$24,MATCH($B7,Kebutuhan!$C$5:$C$24,0)) -> /30 | F7: =INDEX(Kebutuhan!$I$5:$I$24,MATCH($B7,Kebutuhan!$C$5:$C$24,0)) -> 255.255.255.252 | G7: ="10."&(Info!$B$5+INT((L7+1)/65536))&"."&INT(MOD((L7+1),65536)/256)&"."&MOD((L7+1),256)&" – "&"10."&(Info!$B$5+INT((L7+K7-2)/65536))&"."&INT(MOD((L7+K7-2),65536)/256)&"."&MOD((L7+K7-2),256) -> 10.16.33.1 – 10.16.33.2 | H7: ="10."&(Info!$B$5+INT((L7+K7-1)/65536))&"."&INT(MOD((L7+K7-1),65536)/256)&"."&MOD((L7+K7-1),256) -> 10.16.33.3 | I7: =IF(INDEX(Kebutuhan!$D$5:$D$24,MATCH($B7,Kebutuhan!$C$5:$C$24,0))="Link","—","10."&(Info!$B$5+INT((L7+1)/65536))&"."&INT(MOD((L7+1),65536)/256)&"."&MOD((L7+1),256)) -> — | J7: =INDEX(Kebutuhan!$E$5:$E$24,MATCH($B7,Kebutuhan!$C$5:$C$24,0)) -> 2 | K7: =INDEX(Kebutuhan!$G$5:$G$24,MATCH($B7,Kebutuhan!$C$5:$C$24,0)) -> 4 | L7: 8448 | M7: =IF(MOD(L7,K7)=0,"OK","TIDAK ALIGNED") -> OK | N7: =IF(L7>=L6+K6,"OK","OVERLAP") -> OK
A8: 4 | B8: WiFi Publik Barat | C8: Sisi R-BARAT | D8: ="10."&(Info!$B$5+INT((L8)/65536))&"."&INT(MOD((L8),65536)/256)&"."&MOD((L8),256) -> 10.16.64.0 | E8: ="/"&INDEX(Kebutuhan!$H$5:$H$24,MATCH($B8,Kebutuhan!$C$5:$C$24,0)) -> /19 | F8: =INDEX(Kebutuhan!$I$5:$I$24,MATCH($B8,Kebutuhan!$C$5:$C$24,0)) -> 255.255.224.0 | G8: ="10."&(Info!$B$5+INT((L8+1)/65536))&"."&INT(MOD((L8+1),65536)/256)&"."&MOD((L8+1),256)&" – "&"10."&(Info!$B$5+INT((L8+K8-2)/65536))&"."&INT(MOD((L8+K8-2),65536)/256)&"."&MOD((L8+K8-2),256) -> 10.16.64.1 – 10.16.95.254 | H8: ="10."&(Info!$B$5+INT((L8+K8-1)/65536))&"."&INT(MOD((L8+K8-1),65536)/256)&"."&MOD((L8+K8-1),256) -> 10.16.95.255 | I8: =IF(INDEX(Kebutuhan!$D$5:$D$24,MATCH($B8,Kebutuhan!$C$5:$C$24,0))="Link","—","10."&(Info!$B$5+INT((L8+1)/65536))&"."&INT(MOD((L8+1),65536)/256)&"."&MOD((L8+1),256)) -> 10.16.64.1 | J8: =INDEX(Kebutuhan!$E$5:$E$24,MATCH($B8,Kebutuhan!$C$5:$C$24,0)) -> 4500 | K8: =INDEX(Kebutuhan!$G$5:$G$24,MATCH($B8,Kebutuhan!$C$5:$C$24,0)) -> 8192 | L8: 16384 | M8: =IF(MOD(L8,K8)=0,"OK","TIDAK ALIGNED") -> OK | N8: =IF(L8>=L7+K7,"OK","OVERLAP") -> OK
A9: 5 | B9: Puskesmas dan Sekolah Barat | C9: Sisi R-BARAT | D9: ="10."&(Info!$B$5+INT((L9)/65536))&"."&INT(MOD((L9),65536)/256)&"."&MOD((L9),256) -> 10.16.96.0 | E9: ="/"&INDEX(Kebutuhan!$H$5:$H$24,MATCH($B9,Kebutuhan!$C$5:$C$24,0)) -> /24 | F9: =INDEX(Kebutuhan!$I$5:$I$24,MATCH($B9,Kebutuhan!$C$5:$C$24,0)) -> 255.255.255.0 | G9: ="10."&(Info!$B$5+INT((L9+1)/65536))&"."&INT(MOD((L9+1),65536)/256)&"."&MOD((L9+1),256)&" – "&"10."&(Info!$B$5+INT((L9+K9-2)/65536))&"."&INT(MOD((L9+K9-2),65536)/256)&"."&MOD((L9+K9-2),256) -> 10.16.96.1 – 10.16.96.254 | H9: ="10."&(Info!$B$5+INT((L9+K9-1)/65536))&"."&INT(MOD((L9+K9-1),65536)/256)&"."&MOD((L9+K9-1),256) -> 10.16.96.255 | I9: =IF(INDEX(Kebutuhan!$D$5:$D$24,MATCH($B9,Kebutuhan!$C$5:$C$24,0))="Link","—","10."&(Info!$B$5+INT((L9+1)/65536))&"."&INT(MOD((L9+1),65536)/256)&"."&MOD((L9+1),256)) -> 10.16.96.1 | J9: =INDEX(Kebutuhan!$E$5:$E$24,MATCH($B9,Kebutuhan!$C$5:$C$24,0)) -> 220 | K9: =INDEX(Kebutuhan!$G$5:$G$24,MATCH($B9,Kebutuhan!$C$5:$C$24,0)) -> 256 | L9: 24576 | M9: =IF(MOD(L9,K9)=0,"OK","TIDAK ALIGNED") -> OK | N9: =IF(L9>=L8+K8,"OK","OVERLAP") -> OK
A10: 6 | B10: L5 PUSAT-BARAT | C10: Sisi R-BARAT | D10: ="10."&(Info!$B$5+INT((L10)/65536))&"."&INT(MOD((L10),65536)/256)&"."&MOD((L10),256) -> 10.16.97.0 | E10: ="/"&INDEX(Kebutuhan!$H$5:$H$24,MATCH($B10,Kebutuhan!$C$5:$C$24,0)) -> /30 | F10: =INDEX(Kebutuhan!$I$5:$I$24,MATCH($B10,Kebutuhan!$C$5:$C$24,0)) -> 255.255.255.252 | G10: ="10."&(Info!$B$5+INT((L10+1)/65536))&"."&INT(MOD((L10+1),65536)/256)&"."&MOD((L10+1),256)&" – "&"10."&(Info!$B$5+INT((L10+K10-2)/65536))&"."&INT(MOD((L10+K10-2),65536)/256)&"."&MOD((L10+K10-2),256) -> 10.16.97.1 – 10.16.97.2 | H10: ="10."&(Info!$B$5+INT((L10+K10-1)/65536))&"."&INT(MOD((L10+K10-1),65536)/256)&"."&MOD((L10+K10-1),256) -> 10.16.97.3 | I10: =IF(INDEX(Kebutuhan!$D$5:$D$24,MATCH($B10,Kebutuhan!$C$5:$C$24,0))="Link","—","10."&(Info!$B$5+INT((L10+1)/65536))&"."&INT(MOD((L10+1),65536)/256)&"."&MOD((L10+1),256)) -> — | J10: =INDEX(Kebutuhan!$E$5:$E$24,MATCH($B10,Kebutuhan!$C$5:$C$24,0)) -> 2 | K10: =INDEX(Kebutuhan!$G$5:$G$24,MATCH($B10,Kebutuhan!$C$5:$C$24,0)) -> 4 | L10: 24832 | M10: =IF(MOD(L10,K10)=0,"OK","TIDAK ALIGNED") -> OK | N10: =IF(L10>=L9+K9,"OK","OVERLAP") -> OK
A11: 7 | B11: WiFi Publik Timur | C11: Sisi R-TIMUR | D11: ="10."&(Info!$B$5+INT((L11)/65536))&"."&INT(MOD((L11),65536)/256)&"."&MOD((L11),256) -> 10.16.128.0 | E11: ="/"&INDEX(Kebutuhan!$H$5:$H$24,MATCH($B11,Kebutuhan!$C$5:$C$24,0)) -> /19 | F11: =INDEX(Kebutuhan!$I$5:$I$24,MATCH($B11,Kebutuhan!$C$5:$C$24,0)) -> 255.255.224.0 | G11: ="10."&(Info!$B$5+INT((L11+1)/65536))&"."&INT(MOD((L11+1),65536)/256)&"."&MOD((L11+1),256)&" – "&"10."&(Info!$B$5+INT((L11+K11-2)/65536))&"."&INT(MOD((L11+K11-2),65536)/256)&"."&MOD((L11+K11-2),256) -> 10.16.128.1 – 10.16.159.254 | H11: ="10."&(Info!$B$5+INT((L11+K11-1)/65536))&"."&INT(MOD((L11+K11-1),65536)/256)&"."&MOD((L11+K11-1),256) -> 10.16.159.255 | I11: =IF(INDEX(Kebutuhan!$D$5:$D$24,MATCH($B11,Kebutuhan!$C$5:$C$24,0))="Link","—","10."&(Info!$B$5+INT((L11+1)/65536))&"."&INT(MOD((L11+1),65536)/256)&"."&MOD((L11+1),256)) -> 10.16.128.1 | J11: =INDEX(Kebutuhan!$E$5:$E$24,MATCH($B11,Kebutuhan!$C$5:$C$24,0)) -> 5500 | K11: =INDEX(Kebutuhan!$G$5:$G$24,MATCH($B11,Kebutuhan!$C$5:$C$24,0)) -> 8192 | L11: 32768 | M11: =IF(MOD(L11,K11)=0,"OK","TIDAK ALIGNED") -> OK | N11: =IF(L11>=L10+K10,"OK","OVERLAP") -> OK
A12: 8 | B12: Sensor Banjir Timur | C12: Sisi R-TIMUR | D12: ="10."&(Info!$B$5+INT((L12)/65536))&"."&INT(MOD((L12),65536)/256)&"."&MOD((L12),256) -> 10.16.160.0 | E12: ="/"&INDEX(Kebutuhan!$H$5:$H$24,MATCH($B12,Kebutuhan!$C$5:$C$24,0)) -> /22 | F12: =INDEX(Kebutuhan!$I$5:$I$24,MATCH($B12,Kebutuhan!$C$5:$C$24,0)) -> 255.255.252.0 | G12: ="10."&(Info!$B$5+INT((L12+1)/65536))&"."&INT(MOD((L12+1),65536)/256)&"."&MOD((L12+1),256)&" – "&"10."&(Info!$B$5+INT((L12+K12-2)/65536))&"."&INT(MOD((L12+K12-2),65536)/256)&"."&MOD((L12+K12-2),256) -> 10.16.160.1 – 10.16.163.254 | H12: ="10."&(Info!$B$5+INT((L12+K12-1)/65536))&"."&INT(MOD((L12+K12-1),65536)/256)&"."&MOD((L12+K12-1),256) -> 10.16.163.255 | I12: =IF(INDEX(Kebutuhan!$D$5:$D$24,MATCH($B12,Kebutuhan!$C$5:$C$24,0))="Link","—","10."&(Info!$B$5+INT((L12+1)/65536))&"."&INT(MOD((L12+1),65536)/256)&"."&MOD((L12+1),256)) -> 10.16.160.1 | J12: =INDEX(Kebutuhan!$E$5:$E$24,MATCH($B12,Kebutuhan!$C$5:$C$24,0)) -> 700 | K12: =INDEX(Kebutuhan!$G$5:$G$24,MATCH($B12,Kebutuhan!$C$5:$C$24,0)) -> 1024 | L12: 40960 | M12: =IF(MOD(L12,K12)=0,"OK","TIDAK ALIGNED") -> OK | N12: =IF(L12>=L11+K11,"OK","OVERLAP") -> OK
A13: 9 | B13: L4 PUSAT-TIMUR | C13: Sisi R-TIMUR | D13: ="10."&(Info!$B$5+INT((L13)/65536))&"."&INT(MOD((L13),65536)/256)&"."&MOD((L13),256) -> 10.16.164.0 | E13: ="/"&INDEX(Kebutuhan!$H$5:$H$24,MATCH($B13,Kebutuhan!$C$5:$C$24,0)) -> /30 | F13: =INDEX(Kebutuhan!$I$5:$I$24,MATCH($B13,Kebutuhan!$C$5:$C$24,0)) -> 255.255.255.252 | G13: ="10."&(Info!$B$5+INT((L13+1)/65536))&"."&INT(MOD((L13+1),65536)/256)&"."&MOD((L13+1),256)&" – "&"10."&(Info!$B$5+INT((L13+K13-2)/65536))&"."&INT(MOD((L13+K13-2),65536)/256)&"."&MOD((L13+K13-2),256) -> 10.16.164.1 – 10.16.164.2 | H13: ="10."&(Info!$B$5+INT((L13+K13-1)/65536))&"."&INT(MOD((L13+K13-1),65536)/256)&"."&MOD((L13+K13-1),256) -> 10.16.164.3 | I13: =IF(INDEX(Kebutuhan!$D$5:$D$24,MATCH($B13,Kebutuhan!$C$5:$C$24,0))="Link","—","10."&(Info!$B$5+INT((L13+1)/65536))&"."&INT(MOD((L13+1),65536)/256)&"."&MOD((L13+1),256)) -> — | J13: =INDEX(Kebutuhan!$E$5:$E$24,MATCH($B13,Kebutuhan!$C$5:$C$24,0)) -> 2 | K13: =INDEX(Kebutuhan!$G$5:$G$24,MATCH($B13,Kebutuhan!$C$5:$C$24,0)) -> 4 | L13: 41984 | M13: =IF(MOD(L13,K13)=0,"OK","TIDAK ALIGNED") -> OK | N13: =IF(L13>=L12+K12,"OK","OVERLAP") -> OK
A14: 10 | B14: WiFi Publik Selatan | C14: Sisi R-SELATAN | D14: ="10."&(Info!$B$5+INT((L14)/65536))&"."&INT(MOD((L14),65536)/256)&"."&MOD((L14),256) -> 10.16.192.0 | E14: ="/"&INDEX(Kebutuhan!$H$5:$H$24,MATCH($B14,Kebutuhan!$C$5:$C$24,0)) -> /19 | F14: =INDEX(Kebutuhan!$I$5:$I$24,MATCH($B14,Kebutuhan!$C$5:$C$24,0)) -> 255.255.224.0 | G14: ="10."&(Info!$B$5+INT((L14+1)/65536))&"."&INT(MOD((L14+1),65536)/256)&"."&MOD((L14+1),256)&" – "&"10."&(Info!$B$5+INT((L14+K14-2)/65536))&"."&INT(MOD((L14+K14-2),65536)/256)&"."&MOD((L14+K14-2),256) -> 10.16.192.1 – 10.16.223.254 | H14: ="10."&(Info!$B$5+INT((L14+K14-1)/65536))&"."&INT(MOD((L14+K14-1),65536)/256)&"."&MOD((L14+K14-1),256) -> 10.16.223.255 | I14: =IF(INDEX(Kebutuhan!$D$5:$D$24,MATCH($B14,Kebutuhan!$C$5:$C$24,0))="Link","—","10."&(Info!$B$5+INT((L14+1)/65536))&"."&INT(MOD((L14+1),65536)/256)&"."&MOD((L14+1),256)) -> 10.16.192.1 | J14: =INDEX(Kebutuhan!$E$5:$E$24,MATCH($B14,Kebutuhan!$C$5:$C$24,0)) -> 6500 | K14: =INDEX(Kebutuhan!$G$5:$G$24,MATCH($B14,Kebutuhan!$C$5:$C$24,0)) -> 8192 | L14: 49152 | M14: =IF(MOD(L14,K14)=0,"OK","TIDAK ALIGNED") -> OK | N14: =IF(L14>=L13+K13,"OK","OVERLAP") -> OK
A15: 11 | B15: PJU Pintar Selatan | C15: Sisi R-SELATAN | D15: ="10."&(Info!$B$5+INT((L15)/65536))&"."&INT(MOD((L15),65536)/256)&"."&MOD((L15),256) -> 10.16.224.0 | E15: ="/"&INDEX(Kebutuhan!$H$5:$H$24,MATCH($B15,Kebutuhan!$C$5:$C$24,0)) -> /25 | F15: =INDEX(Kebutuhan!$I$5:$I$24,MATCH($B15,Kebutuhan!$C$5:$C$24,0)) -> 255.255.255.128 | G15: ="10."&(Info!$B$5+INT((L15+1)/65536))&"."&INT(MOD((L15+1),65536)/256)&"."&MOD((L15+1),256)&" – "&"10."&(Info!$B$5+INT((L15+K15-2)/65536))&"."&INT(MOD((L15+K15-2),65536)/256)&"."&MOD((L15+K15-2),256) -> 10.16.224.1 – 10.16.224.126 | H15: ="10."&(Info!$B$5+INT((L15+K15-1)/65536))&"."&INT(MOD((L15+K15-1),65536)/256)&"."&MOD((L15+K15-1),256) -> 10.16.224.127 | I15: =IF(INDEX(Kebutuhan!$D$5:$D$24,MATCH($B15,Kebutuhan!$C$5:$C$24,0))="Link","—","10."&(Info!$B$5+INT((L15+1)/65536))&"."&INT(MOD((L15+1),65536)/256)&"."&MOD((L15+1),256)) -> 10.16.224.1 | J15: =INDEX(Kebutuhan!$E$5:$E$24,MATCH($B15,Kebutuhan!$C$5:$C$24,0)) -> 90 | K15: =INDEX(Kebutuhan!$G$5:$G$24,MATCH($B15,Kebutuhan!$C$5:$C$24,0)) -> 128 | L15: 57344 | M15: =IF(MOD(L15,K15)=0,"OK","TIDAK ALIGNED") -> OK | N15: =IF(L15>=L14+K14,"OK","OVERLAP") -> OK
A16: 12 | B16: L3 PUSAT-SELATAN | C16: Sisi R-SELATAN | D16: ="10."&(Info!$B$5+INT((L16)/65536))&"."&INT(MOD((L16),65536)/256)&"."&MOD((L16),256) -> 10.16.224.128 | E16: ="/"&INDEX(Kebutuhan!$H$5:$H$24,MATCH($B16,Kebutuhan!$C$5:$C$24,0)) -> /30 | F16: =INDEX(Kebutuhan!$I$5:$I$24,MATCH($B16,Kebutuhan!$C$5:$C$24,0)) -> 255.255.255.252 | G16: ="10."&(Info!$B$5+INT((L16+1)/65536))&"."&INT(MOD((L16+1),65536)/256)&"."&MOD((L16+1),256)&" – "&"10."&(Info!$B$5+INT((L16+K16-2)/65536))&"."&INT(MOD((L16+K16-2),65536)/256)&"."&MOD((L16+K16-2),256) -> 10.16.224.129 – 10.16.224.130 | H16: ="10."&(Info!$B$5+INT((L16+K16-1)/65536))&"."&INT(MOD((L16+K16-1),65536)/256)&"."&MOD((L16+K16-1),256) -> 10.16.224.131 | I16: =IF(INDEX(Kebutuhan!$D$5:$D$24,MATCH($B16,Kebutuhan!$C$5:$C$24,0))="Link","—","10."&(Info!$B$5+INT((L16+1)/65536))&"."&INT(MOD((L16+1),65536)/256)&"."&MOD((L16+1),256)) -> — | J16: =INDEX(Kebutuhan!$E$5:$E$24,MATCH($B16,Kebutuhan!$C$5:$C$24,0)) -> 2 | K16: =INDEX(Kebutuhan!$G$5:$G$24,MATCH($B16,Kebutuhan!$C$5:$C$24,0)) -> 4 | L16: 57472 | M16: =IF(MOD(L16,K16)=0,"OK","TIDAK ALIGNED") -> OK | N16: =IF(L16>=L15+K15,"OK","OVERLAP") -> OK
A17: 13 | B17: Pegawai Balai Kota | C17: Balai Kota (R-PUSAT) | D17: ="10."&(Info!$B$5+INT((L17)/65536))&"."&INT(MOD((L17),65536)/256)&"."&MOD((L17),256) -> 10.17.0.0 | E17: ="/"&INDEX(Kebutuhan!$H$5:$H$24,MATCH($B17,Kebutuhan!$C$5:$C$24,0)) -> /21 | F17: =INDEX(Kebutuhan!$I$5:$I$24,MATCH($B17,Kebutuhan!$C$5:$C$24,0)) -> 255.255.248.0 | G17: ="10."&(Info!$B$5+INT((L17+1)/65536))&"."&INT(MOD((L17+1),65536)/256)&"."&MOD((L17+1),256)&" – "&"10."&(Info!$B$5+INT((L17+K17-2)/65536))&"."&INT(MOD((L17+K17-2),65536)/256)&"."&MOD((L17+K17-2),256) -> 10.17.0.1 – 10.17.7.254 | H17: ="10."&(Info!$B$5+INT((L17+K17-1)/65536))&"."&INT(MOD((L17+K17-1),65536)/256)&"."&MOD((L17+K17-1),256) -> 10.17.7.255 | I17: =IF(INDEX(Kebutuhan!$D$5:$D$24,MATCH($B17,Kebutuhan!$C$5:$C$24,0))="Link","—","10."&(Info!$B$5+INT((L17+1)/65536))&"."&INT(MOD((L17+1),65536)/256)&"."&MOD((L17+1),256)) -> 10.17.0.1 | J17: =INDEX(Kebutuhan!$E$5:$E$24,MATCH($B17,Kebutuhan!$C$5:$C$24,0)) -> 1800 | K17: =INDEX(Kebutuhan!$G$5:$G$24,MATCH($B17,Kebutuhan!$C$5:$C$24,0)) -> 2048 | L17: 65536 | M17: =IF(MOD(L17,K17)=0,"OK","TIDAK ALIGNED") -> OK | N17: =IF(L17>=L16+K16,"OK","OVERLAP") -> OK
... A24: 20 | B24: L2 PUSAT-UTARA | C24: Sisi R-UTARA | D24: ="10."&(Info!$B$5+INT((L24)/65536))&"."&INT(MOD((L24),65536)/256)&"."&MOD((L24),256) -> 10.18.130.0 | E24: ="/"&INDEX(Kebutuhan!$H$5:$H$24,MATCH($B24,Kebutuhan!$C$5:$C$24,0)) -> /30 | F24: =INDEX(Kebutuhan!$I$5:$I$24,MATCH($B24,Kebutuhan!$C$5:$C$24,0)) -> 255.255.255.252 | G24: ="10."&(Info!$B$5+INT((L24+1)/65536))&"."&INT(MOD((L24+1),65536)/256)&"."&MOD((L24+1),256)&" – "&"10."&(Info!$B$5+INT((L24+K24-2)/65536))&"."&INT(MOD((L24+K24-2),65536)/256)&"."&MOD((L24+K24-2),256) -> 10.18.130.1 – 10.18.130.2 | H24: ="10."&(Info!$B$5+INT((L24+K24-1)/65536))&"."&INT(MOD((L24+K24-1),65536)/256)&"."&MOD((L24+K24-1),256) -> 10.18.130.3 | I24: =IF(INDEX(Kebutuhan!$D$5:$D$24,MATCH($B24,Kebutuhan!$C$5:$C$24,0))="Link","—","10."&(Info!$B$5+INT((L24+1)/65536))&"."&INT(MOD((L24+1),65536)/256)&"."&MOD((L24+1),256)) -> — | J24: =INDEX(Kebutuhan!$E$5:$E$24,MATCH($B24,Kebutuhan!$C$5:$C$24,0)) -> 2 | K24: =INDEX(Kebutuhan!$G$5:$G$24,MATCH($B24,Kebutuhan!$C$5:$C$24,0)) -> 4 | L24: 164352 | M24: =IF(MOD(L24,K24)=0,"OK","TIDAK ALIGNED") -> OK | N24: =IF(L24>=L23+K23,"OK","OVERLAP") -> OK
B26: Ringkasan | C26: Nilai
B27: Total ukuran blok | C27: =SUM(K5:K24) -> 61752
B28: Total host terpakai | C28: =SUM(J5:J24) -> 42092
B29: Prefix induk (akar pohon) | C29: =Supernet!$D$5 -> 14
B30: Ukuran blok induk | C30: =2^(32-C29) -> 262144
B31: Blok induk | C31: ="10."&Info!$B$5&".0.0/"&C29 -> 10.16.0.0/14

Sheet Supernet
A1: Pohon Penggabungan CIDR (Supernet per Router)
A2: Aturan gabung: prefix sama → naik 1; prefix beda → ambil blok terbesar lalu naik 1. Alokasi atas ke bawah: anak terbesar di awal, anak kedua di awal paruh kedua.
A4: Level | B4: Blok | C4: Anggota | D4: Prefix | E4: Offset | F4: Network / prefix | G4: Rentang alamat | H4: Jumlah alamat | I4: Cek aligned
A5: 0 | B5: Induk | C5: Semua jaringan | D5: 14 | E5: 0 | F5: ="10."&(Info!$B$5+INT((E5)/65536))&"."&INT(MOD((E5),65536)/256)&"."&MOD((E5),256)&"/"&D5 -> 10.16.0.0/14 | G5: ="10."&(Info!$B$5+INT((E5)/65536))&"."&INT(MOD((E5),65536)/256)&"."&MOD((E5),256)&" – "&"10."&(Info!$B$5+INT((E5+H5-1)/65536))&"."&INT(MOD((E5+H5-1),65536)/256)&"."&MOD((E5+H5-1),256) -> 10.16.0.0 – 10.19.255.255 | H5: =2^(32-D5) -> 262144 | I5: =IF(MOD(E5,H5)=0,"OK","TIDAK ALIGNED") -> OK
A6: 1 | B6: 4 wilayah + Balai Kota | C6: DC, Barat, Timur, Selatan, Balai Kota | D6: 15 | E6: 0 | F6: ="10."&(Info!$B$5+INT((E6)/65536))&"."&INT(MOD((E6),65536)/256)&"."&MOD((E6),256)&"/"&D6 -> 10.16.0.0/15 | G6: ="10."&(Info!$B$5+INT((E6)/65536))&"."&INT(MOD((E6),65536)/256)&"."&MOD((E6),256)&" – "&"10."&(Info!$B$5+INT((E6+H6-1)/65536))&"."&INT(MOD((E6+H6-1),65536)/256)&"."&MOD((E6+H6-1),256) -> 10.16.0.0 – 10.17.255.255 | H6: =2^(32-D6) -> 131072 | I6: =IF(MOD(E6,H6)=0,"OK","TIDAK ALIGNED") -> OK
A7: 2 | B7: DC + Barat + Timur + Selatan | C7: 4 sisi router wilayah | D7: 16 | E7: 0 | F7: ="10."&(Info!$B$5+INT((E7)/65536))&"."&INT(MOD((E7),65536)/256)&"."&MOD((E7),256)&"/"&D7 -> 10.16.0.0/16 | G7: ="10."&(Info!$B$5+INT((E7)/65536))&"."&INT(MOD((E7),65536)/256)&"."&MOD((E7),256)&" – "&"10."&(Info!$B$5+INT((E7+H7-1)/65536))&"."&INT(MOD((E7+H7-1),65536)/256)&"."&MOD((E7+H7-1),256) -> 10.16.0.0 – 10.16.255.255 | H7: =2^(32-D7) -> 65536 | I7: =IF(MOD(E7,H7)=0,"OK","TIDAK ALIGNED") -> OK
A8: 3 | B8: DC + Barat | C8: Sisi R-DC + sisi R-BARAT | D8: 17 | E8: 0 | F8: ="10."&(Info!$B$5+INT((E8)/65536))&"."&INT(MOD((E8),65536)/256)&"."&MOD((E8),256)&"/"&D8 -> 10.16.0.0/17 | G8: ="10."&(Info!$B$5+INT((E8)/65536))&"."&INT(MOD((E8),65536)/256)&"."&MOD((E8),256)&" – "&"10."&(Info!$B$5+INT((E8+H8-1)/65536))&"."&INT(MOD((E8+H8-1),65536)/256)&"."&MOD((E8+H8-1),256) -> 10.16.0.0 – 10.16.127.255 | H8: =2^(32-D8) -> 32768 | I8: =IF(MOD(E8,H8)=0,"OK","TIDAK ALIGNED") -> OK
A9: 4 | B9: Sisi R-DC | C9: CCTV /19 + (Server DC /24 + L1 /30) | D9: 18 | E9: 0 | F9: ="10."&(Info!$B$5+INT((E9)/65536))&"."&INT(MOD((E9),65536)/256)&"."&MOD((E9),256)&"/"&D9 -> 10.16.0.0/18 | G9: ="10."&(Info!$B$5+INT((E9)/65536))&"."&INT(MOD((E9),65536)/256)&"."&MOD((E9),256)&" – "&"10."&(Info!$B$5+INT((E9+H9-1)/65536))&"."&INT(MOD((E9+H9-1),65536)/256)&"."&MOD((E9+H9-1),256) -> 10.16.0.0 – 10.16.63.255 | H9: =2^(32-D9) -> 16384 | I9: =IF(MOD(E9,H9)=0,"OK","TIDAK ALIGNED") -> OK
A10: 5 | B10: Server DC + L1 | C10: Server dan Storage DC /24 + L1 /30 | D10: 23 | E10: 8192 | F10: ="10."&(Info!$B$5+INT((E10)/65536))&"."&INT(MOD((E10),65536)/256)&"."&MOD((E10),256)&"/"&D10 -> 10.16.32.0/23 | G10: ="10."&(Info!$B$5+INT((E10)/65536))&"."&INT(MOD((E10),65536)/256)&"."&MOD((E10),256)&" – "&"10."&(Info!$B$5+INT((E10+H10-1)/65536))&"."&INT(MOD((E10+H10-1),65536)/256)&"."&MOD((E10+H10-1),256) -> 10.16.32.0 – 10.16.33.255 | H10: =2^(32-D10) -> 512 | I10: =IF(MOD(E10,H10)=0,"OK","TIDAK ALIGNED") -> OK
A11: 4 | B11: Sisi R-BARAT | C11: WiFi Barat /19 + (Puskesmas /24 + L5 /30) | D11: 18 | E11: 16384 | F11: ="10."&(Info!$B$5+INT((E11)/65536))&"."&INT(MOD((E11),65536)/256)&"."&MOD((E11),256)&"/"&D11 -> 10.16.64.0/18 | G11: ="10."&(Info!$B$5+INT((E11)/65536))&"."&INT(MOD((E11),65536)/256)&"."&MOD((E11),256)&" – "&"10."&(Info!$B$5+INT((E11+H11-1)/65536))&"."&INT(MOD((E11+H11-1),65536)/256)&"."&MOD((E11+H11-1),256) -> 10.16.64.0 – 10.16.127.255 | H11: =2^(32-D11) -> 16384 | I11: =IF(MOD(E11,H11)=0,"OK","TIDAK ALIGNED") -> OK
A12: 5 | B12: Puskesmas + L5 | C12: Puskesmas dan Sekolah /24 + L5 /30 | D12: 23 | E12: 24576 | F12: ="10."&(Info!$B$5+INT((E12)/65536))&"."&INT(MOD((E12),65536)/256)&"."&MOD((E12),256)&"/"&D12 -> 10.16.96.0/23 | G12: ="10."&(Info!$B$5+INT((E12)/65536))&"."&INT(MOD((E12),65536)/256)&"."&MOD((E12),256)&" – "&"10."&(Info!$B$5+INT((E12+H12-1)/65536))&"."&INT(MOD((E12+H12-1),65536)/256)&"."&MOD((E12+H12-1),256) -> 10.16.96.0 – 10.16.97.255 | H12: =2^(32-D12) -> 512 | I12: =IF(MOD(E12,H12)=0,"OK","TIDAK ALIGNED") -> OK
A13: 3 | B13: Timur + Selatan | C13: Sisi R-TIMUR + sisi R-SELATAN | D13: 17 | E13: 32768 | F13: ="10."&(Info!$B$5+INT((E13)/65536))&"."&INT(MOD((E13),65536)/256)&"."&MOD((E13),256)&"/"&D13 -> 10.16.128.0/17 | G13: ="10."&(Info!$B$5+INT((E13)/65536))&"."&INT(MOD((E13),65536)/256)&"."&MOD((E13),256)&" – "&"10."&(Info!$B$5+INT((E13+H13-1)/65536))&"."&INT(MOD((E13+H13-1),65536)/256)&"."&MOD((E13+H13-1),256) -> 10.16.128.0 – 10.16.255.255 | H13: =2^(32-D13) -> 32768 | I13: =IF(MOD(E13,H13)=0,"OK","TIDAK ALIGNED") -> OK
A14: 4 | B14: Sisi R-TIMUR | C14: WiFi Timur /19 + (Banjir /22 + L4 /30) | D14: 18 | E14: 32768 | F14: ="10."&(Info!$B$5+INT((E14)/65536))&"."&INT(MOD((E14),65536)/256)&"."&MOD((E14),256)&"/"&D14 -> 10.16.128.0/18 | G14: ="10."&(Info!$B$5+INT((E14)/65536))&"."&INT(MOD((E14),65536)/256)&"."&MOD((E14),256)&" – "&"10."&(Info!$B$5+INT((E14+H14-1)/65536))&"."&INT(MOD((E14+H14-1),65536)/256)&"."&MOD((E14+H14-1),256) -> 10.16.128.0 – 10.16.191.255 | H14: =2^(32-D14) -> 16384 | I14: =IF(MOD(E14,H14)=0,"OK","TIDAK ALIGNED") -> OK
A15: 5 | B15: Banjir + L4 | C15: Sensor Banjir /22 + L4 /30 | D15: 21 | E15: 40960 | F15: ="10."&(Info!$B$5+INT((E15)/65536))&"."&INT(MOD((E15),65536)/256)&"."&MOD((E15),256)&"/"&D15 -> 10.16.160.0/21 | G15: ="10."&(Info!$B$5+INT((E15)/65536))&"."&INT(MOD((E15),65536)/256)&"."&MOD((E15),256)&" – "&"10."&(Info!$B$5+INT((E15+H15-1)/65536))&"."&INT(MOD((E15+H15-1),65536)/256)&"."&MOD((E15+H15-1),256) -> 10.16.160.0 – 10.16.167.255 | H15: =2^(32-D15) -> 2048 | I15: =IF(MOD(E15,H15)=0,"OK","TIDAK ALIGNED") -> OK
A16: 4 | B16: Sisi R-SELATAN | C16: WiFi Selatan /19 + (PJU /25 + L3 /30) | D16: 18 | E16: 49152 | F16: ="10."&(Info!$B$5+INT((E16)/65536))&"."&INT(MOD((E16),65536)/256)&"."&MOD((E16),256)&"/"&D16 -> 10.16.192.0/18 | G16: ="10."&(Info!$B$5+INT((E16)/65536))&"."&INT(MOD((E16),65536)/256)&"."&MOD((E16),256)&" – "&"10."&(Info!$B$5+INT((E16+H16-1)/65536))&"."&INT(MOD((E16+H16-1),65536)/256)&"."&MOD((E16+H16-1),256) -> 10.16.192.0 – 10.16.255.255 | H16: =2^(32-D16) -> 16384 | I16: =IF(MOD(E16,H16)=0,"OK","TIDAK ALIGNED") -> OK
... A23: 2 | B23: Sensor + L2 | C23: Sensor Lalu Lintas /23 + L2 /30 | D23: 22 | E23: 163840 | F23: ="10."&(Info!$B$5+INT((E23)/65536))&"."&INT(MOD((E23),65536)/256)&"."&MOD((E23),256)&"/"&D23 -> 10.18.128.0/22 | G23: ="10."&(Info!$B$5+INT((E23)/65536))&"."&INT(MOD((E23),65536)/256)&"."&MOD((E23),256)&" – "&"10."&(Info!$B$5+INT((E23+H23-1)/65536))&"."&INT(MOD((E23+H23-1),65536)/256)&"."&MOD((E23+H23-1),256) -> 10.18.128.0 – 10.18.131.255 | H23: =2^(32-D23) -> 1024 | I23: =IF(MOD(E23,H23)=0,"OK","TIDAK ALIGNED") -> OK
A26: Rencana rute ringkas (acuan soal 3, perlu dicek Fathur)
B27: Router | C27: Tujuan | D27: Jaringan | F27: Next hop | G27: Keterangan
B28: R-PUSAT | C28: LAN sisi R-DC | D28: =F9 -> 10.16.0.0/18 | F28: ="10."&(Info!$B$5+INT((INDEX(CIDR!$L$5:$L$24,MATCH("L1 PUSAT-DC",CIDR!$B$5:$B$24,0))+2)/65536))&"."&INT(MOD((INDEX(CIDR!$L$5:$L$24,MATCH("L1 PUSAT-DC",CIDR!$B$5:$B$24,0))+2),65536)/256)&"."&MOD((INDEX(CIDR!$L$5:$L$24,MATCH("L1 PUSAT-DC",CIDR!$B$5:$B$24,0))+2),256) -> 10.16.33.2 | G28: via L1
B29: R-PUSAT | C29: LAN sisi R-BARAT | D29: =F11 -> 10.16.64.0/18 | F29: ="10."&(Info!$B$5+INT((INDEX(CIDR!$L$5:$L$24,MATCH("L5 PUSAT-BARAT",CIDR!$B$5:$B$24,0))+2)/65536))&"."&INT(MOD((INDEX(CIDR!$L$5:$L$24,MATCH("L5 PUSAT-BARAT",CIDR!$B$5:$B$24,0))+2),65536)/256)&"."&MOD((INDEX(CIDR!$L$5:$L$24,MATCH("L5 PUSAT-BARAT",CIDR!$B$5:$B$24,0))+2),256) -> 10.16.97.2 | G29: via L5
B30: R-PUSAT | C30: LAN sisi R-TIMUR | D30: =F14 -> 10.16.128.0/18 | F30: ="10."&(Info!$B$5+INT((INDEX(CIDR!$L$5:$L$24,MATCH("L4 PUSAT-TIMUR",CIDR!$B$5:$B$24,0))+2)/65536))&"."&INT(MOD((INDEX(CIDR!$L$5:$L$24,MATCH("L4 PUSAT-TIMUR",CIDR!$B$5:$B$24,0))+2),65536)/256)&"."&MOD((INDEX(CIDR!$L$5:$L$24,MATCH("L4 PUSAT-TIMUR",CIDR!$B$5:$B$24,0))+2),256) -> 10.16.164.2 | G30: via L4
B31: R-PUSAT | C31: LAN sisi R-SELATAN | D31: =F16 -> 10.16.192.0/18 | F31: ="10."&(Info!$B$5+INT((INDEX(CIDR!$L$5:$L$24,MATCH("L3 PUSAT-SELATAN",CIDR!$B$5:$B$24,0))+2)/65536))&"."&INT(MOD((INDEX(CIDR!$L$5:$L$24,MATCH("L3 PUSAT-SELATAN",CIDR!$B$5:$B$24,0))+2),65536)/256)&"."&MOD((INDEX(CIDR!$L$5:$L$24,MATCH("L3 PUSAT-SELATAN",CIDR!$B$5:$B$24,0))+2),256) -> 10.16.224.130 | G31: via L3
B32: R-PUSAT | C32: LAN R-UTARA + R-PELABUHAN | D32: =F19 -> 10.18.0.0/16 | F32: ="10."&(Info!$B$5+INT((INDEX(CIDR!$L$5:$L$24,MATCH("L2 PUSAT-UTARA",CIDR!$B$5:$B$24,0))+2)/65536))&"."&INT(MOD((INDEX(CIDR!$L$5:$L$24,MATCH("L2 PUSAT-UTARA",CIDR!$B$5:$B$24,0))+2),65536)/256)&"."&MOD((INDEX(CIDR!$L$5:$L$24,MATCH("L2 PUSAT-UTARA",CIDR!$B$5:$B$24,0))+2),256) -> 10.18.130.2 | G32: via L2; trafik Balai Kota ke Pelabuhan nanti lewat tunnel GRE (soal 6)
B33: R-PUSAT | C33: Default (internet) | D33: 0.0.0.0/0 | F33: ="203.0.113."&(4*Info!$B$4+1) -> 203.0.113.9 | G33: R-ISP; asumsi R-ISP host pertama link ISP
B34: R-UTARA | C34: LAN R-PELABUHAN | D34: =F21 -> 10.18.64.0/18 | F34: ="10."&(Info!$B$5+INT((INDEX(CIDR!$L$5:$L$24,MATCH("L6 UTARA-PELABUHAN",CIDR!$B$5:$B$24,0))+2)/65536))&"."&INT(MOD((INDEX(CIDR!$L$5:$L$24,MATCH("L6 UTARA-PELABUHAN",CIDR!$B$5:$B$24,0))+2),65536)/256)&"."&MOD((INDEX(CIDR!$L$5:$L$24,MATCH("L6 UTARA-PELABUHAN",CIDR!$B$5:$B$24,0))+2),256) -> 10.18.96.130 | G34: via L6
B35: R-UTARA | C35: Default | D35: 0.0.0.0/0 | F35: ="10."&(Info!$B$5+INT((INDEX(CIDR!$L$5:$L$24,MATCH("L2 PUSAT-UTARA",CIDR!$B$5:$B$24,0))+1)/65536))&"."&INT(MOD((INDEX(CIDR!$L$5:$L$24,MATCH("L2 PUSAT-UTARA",CIDR!$B$5:$B$24,0))+1),65536)/256)&"."&MOD((INDEX(CIDR!$L$5:$L$24,MATCH("L2 PUSAT-UTARA",CIDR!$B$5:$B$24,0))+1),256) -> 10.18.130.1 | G35: ke R-PUSAT
B36: R-DC | C36: Default | D36: 0.0.0.0/0 | F36: ="10."&(Info!$B$5+INT((INDEX(CIDR!$L$5:$L$24,MATCH("L1 PUSAT-DC",CIDR!$B$5:$B$24,0))+1)/65536))&"."&INT(MOD((INDEX(CIDR!$L$5:$L$24,MATCH("L1 PUSAT-DC",CIDR!$B$5:$B$24,0))+1),65536)/256)&"."&MOD((INDEX(CIDR!$L$5:$L$24,MATCH("L1 PUSAT-DC",CIDR!$B$5:$B$24,0))+1),256) -> 10.16.33.1 | G36: ke R-PUSAT
B37: R-BARAT | C37: Default | D37: 0.0.0.0/0 | F37: ="10."&(Info!$B$5+INT((INDEX(CIDR!$L$5:$L$24,MATCH("L5 PUSAT-BARAT",CIDR!$B$5:$B$24,0))+1)/65536))&"."&INT(MOD((INDEX(CIDR!$L$5:$L$24,MATCH("L5 PUSAT-BARAT",CIDR!$B$5:$B$24,0))+1),65536)/256)&"."&MOD((INDEX(CIDR!$L$5:$L$24,MATCH("L5 PUSAT-BARAT",CIDR!$B$5:$B$24,0))+1),256) -> 10.16.97.1 | G37: ke R-PUSAT
B38: R-TIMUR | C38: Default | D38: 0.0.0.0/0 | F38: ="10."&(Info!$B$5+INT((INDEX(CIDR!$L$5:$L$24,MATCH("L4 PUSAT-TIMUR",CIDR!$B$5:$B$24,0))+1)/65536))&"."&INT(MOD((INDEX(CIDR!$L$5:$L$24,MATCH("L4 PUSAT-TIMUR",CIDR!$B$5:$B$24,0))+1),65536)/256)&"."&MOD((INDEX(CIDR!$L$5:$L$24,MATCH("L4 PUSAT-TIMUR",CIDR!$B$5:$B$24,0))+1),256) -> 10.16.164.1 | G38: ke R-PUSAT
B39: R-SELATAN | C39: Default | D39: 0.0.0.0/0 | F39: ="10."&(Info!$B$5+INT((INDEX(CIDR!$L$5:$L$24,MATCH("L3 PUSAT-SELATAN",CIDR!$B$5:$B$24,0))+1)/65536))&"."&INT(MOD((INDEX(CIDR!$L$5:$L$24,MATCH("L3 PUSAT-SELATAN",CIDR!$B$5:$B$24,0))+1),65536)/256)&"."&MOD((INDEX(CIDR!$L$5:$L$24,MATCH("L3 PUSAT-SELATAN",CIDR!$B$5:$B$24,0))+1),256) -> 10.16.224.129 | G39: ke R-PUSAT
B40: R-PELABUHAN | C40: Default | D40: 0.0.0.0/0 | F40: ="10."&(Info!$B$5+INT((INDEX(CIDR!$L$5:$L$24,MATCH("L6 UTARA-PELABUHAN",CIDR!$B$5:$B$24,0))+1)/65536))&"."&INT(MOD((INDEX(CIDR!$L$5:$L$24,MATCH("L6 UTARA-PELABUHAN",CIDR!$B$5:$B$24,0))+1),65536)/256)&"."&MOD((INDEX(CIDR!$L$5:$L$24,MATCH("L6 UTARA-PELABUHAN",CIDR!$B$5:$B$24,0))+1),256) -> 10.18.96.129 | G40: ke R-UTARA

Sheet Efisiensi
A1: Perbandingan Efisiensi VLSM vs CIDR (Soal UTS 5)
A2: Pemakaian = host terpakai (LAN + 2 per link) ÷ ukuran blok induk.
A4: Metode | B4: Prefix induk | C4: Ukuran blok induk | D4: Total ukuran blok subnet | E4: Host terpakai | F4: Pemakaian | G4: Alamat terbuang
A5: VLSM | B5: ="/"&VLSM!C29 -> /16 | C5: =VLSM!C30 -> 65536 | D5: =VLSM!C27 -> 61752 | E5: =VLSM!C28 -> 42092 | F5: =E5/C5 -> 0.64227295 | G5: =C5-E5 -> 23444
A6: CIDR | B6: ="/"&CIDR!C29 -> /14 | C6: =CIDR!C30 -> 262144 | D6: =CIDR!C27 -> 61752 | E6: =CIDR!C28 -> 42092 | F6: =E6/C6 -> 0.16056824 | G6: =C6-E6 -> 220052
A8: Selisih pemakaian | B8: =F5-F6 -> 0.48170471
A9: Metode lebih efisien | B9: =IF(F5>F6,"VLSM","CIDR") -> VLSM
A11: Alasan: VLSM menempatkan subnet berurutan tanpa celah, sehingga blok induk hanya /16. CIDR membulatkan setiap sisi router ke blok 2^n (misalnya sisi Utara yang hanya berisi ±25 ribu alamat menjadi /16), sehingga induknya /14. Imbalannya, CIDR membuat rute dan ACL jauh lebih ringkas.

Sheet Revisi
A1: Tabel Revisi terhadap Lembar Jawaban UTS (23 Oktober 2026)
A2: Kolom 'Jawaban UTS' disalin dari foto lembar jawaban; kolom 'Perbaikan' mengambil nilai dari sheet VLSM/CIDR.
A4: No | B4: Soal / bagian | C4: Subnet | D4: Jawaban UTS | E4: Perbaikan | F4: Alasan kesalahan
A5: 1 | B5: Soal 5 (VLSM) | C5: Prefix induk VLSM | D5: /17 | E5: ="/"&VLSM!C29 -> /16 | F5: Total blok 61.752 > 32.768 (/17), sehingga butuh /16 (65.536).
A6: 2 | B6: Soal 3 (VLSM) | C6: Pegawai Balai Kota | D6: 10.16.224.0/21 bc 10.16.230.255 | E6: =INDEX(VLSM!$D$5:$D$24,MATCH("Pegawai Balai Kota",VLSM!$B$5:$B$24,0))&INDEX(VLSM!$E$5:$E$24,MATCH("Pegawai Balai Kota",VLSM!$B$5:$B$24,0))&" bc "&INDEX(VLSM!$H$5:$H$24,MATCH("Pegawai Balai Kota",VLSM!$B$5:$B$24,0)) -> 10.16.224.0/21 bc 10.16.231.255 | F6: /21 memakan 8 nilai oktet ke-3 (224–231), bukan 7.
A7: 3 | B7: Soal 3 (VLSM) | C7: Sensor Banjir Timur | D7: 10.16.231.0/22 bc 10.16.234.255 | E7: =INDEX(VLSM!$D$5:$D$24,MATCH("Sensor Banjir Timur",VLSM!$B$5:$B$24,0))&INDEX(VLSM!$E$5:$E$24,MATCH("Sensor Banjir Timur",VLSM!$B$5:$B$24,0))&" bc "&INDEX(VLSM!$H$5:$H$24,MATCH("Sensor Banjir Timur",VLSM!$B$5:$B$24,0)) -> 10.16.232.0/22 bc 10.16.235.255 | F7: Bergeser akibat baris Pegawai; network /22 harus kelipatan 4 pada oktet ke-3.
A8: 4 | B8: Soal 3 (VLSM) | C8: Sensor Lalu Lintas Utara | D8: 10.16.235.0/23 bc 10.16.236.255 | E8: =INDEX(VLSM!$D$5:$D$24,MATCH("Sensor Lalu Lintas Utara",VLSM!$B$5:$B$24,0))&INDEX(VLSM!$E$5:$E$24,MATCH("Sensor Lalu Lintas Utara",VLSM!$B$5:$B$24,0))&" bc "&INDEX(VLSM!$H$5:$H$24,MATCH("Sensor Lalu Lintas Utara",VLSM!$B$5:$B$24,0)) -> 10.16.236.0/23 bc 10.16.237.255 | F8: Bergeser; network /23 harus kelipatan 2 pada oktet ke-3.
A9: 5 | B9: Soal 3 (VLSM) | C9: Puskesmas dan Sekolah Barat | D9: 10.16.237.0/24 bc 10.16.238.255 | E9: =INDEX(VLSM!$D$5:$D$24,MATCH("Puskesmas dan Sekolah Barat",VLSM!$B$5:$B$24,0))&INDEX(VLSM!$E$5:$E$24,MATCH("Puskesmas dan Sekolah Barat",VLSM!$B$5:$B$24,0))&" bc "&INDEX(VLSM!$H$5:$H$24,MATCH("Puskesmas dan Sekolah Barat",VLSM!$B$5:$B$24,0)) -> 10.16.238.0/24 bc 10.16.238.255 | F9: Bergeser, dan /24 hanya memakan 1 nilai oktet ke-3.
A10: 6 | B10: Soal 3 (VLSM) | C10: Server dan Storage DC | D10: 10.16.239.0/24 bc 10.16.240.255 | E10: =INDEX(VLSM!$D$5:$D$24,MATCH("Server dan Storage DC",VLSM!$B$5:$B$24,0))&INDEX(VLSM!$E$5:$E$24,MATCH("Server dan Storage DC",VLSM!$B$5:$B$24,0))&" bc "&INDEX(VLSM!$H$5:$H$24,MATCH("Server dan Storage DC",VLSM!$B$5:$B$24,0)) -> 10.16.239.0/24 bc 10.16.239.255 | F10: /24 hanya memakan 1 nilai oktet ke-3.
A11: 7 | B11: Soal 3 (VLSM) | C11: Kantor Pelabuhan | D11: 10.16.241.0/25 bc 10.16.241.127 | E11: =INDEX(VLSM!$D$5:$D$24,MATCH("Kantor Pelabuhan",VLSM!$B$5:$B$24,0))&INDEX(VLSM!$E$5:$E$24,MATCH("Kantor Pelabuhan",VLSM!$B$5:$B$24,0))&" bc "&INDEX(VLSM!$H$5:$H$24,MATCH("Kantor Pelabuhan",VLSM!$B$5:$B$24,0)) -> 10.16.240.0/25 bc 10.16.240.127 | F11: Bergeser akibat baris sebelumnya.
A12: 8 | B12: Soal 3 (VLSM) | C12: PJU Pintar Selatan | D12: 10.16.241.128/25 bc 10.16.241.255 | E12: =INDEX(VLSM!$D$5:$D$24,MATCH("PJU Pintar Selatan",VLSM!$B$5:$B$24,0))&INDEX(VLSM!$E$5:$E$24,MATCH("PJU Pintar Selatan",VLSM!$B$5:$B$24,0))&" bc "&INDEX(VLSM!$H$5:$H$24,MATCH("PJU Pintar Selatan",VLSM!$B$5:$B$24,0)) -> 10.16.240.128/25 bc 10.16.240.255 | F12: Bergeser akibat baris sebelumnya.
A13: 9 | B13: Soal 3 (VLSM) | C13: Server Balai Kota | D13: 10.16.242.0/27 bc 10.16.242.32 | E13: =INDEX(VLSM!$D$5:$D$24,MATCH("Server Balai Kota",VLSM!$B$5:$B$24,0))&INDEX(VLSM!$E$5:$E$24,MATCH("Server Balai Kota",VLSM!$B$5:$B$24,0))&" bc "&INDEX(VLSM!$H$5:$H$24,MATCH("Server Balai Kota",VLSM!$B$5:$B$24,0)) -> 10.16.241.0/27 bc 10.16.241.31 | F13: Bergeser; broadcast = network + 32 − 1.
A14: 10 | B14: Soal 3 (VLSM) | C14: L1 PUSAT-DC | D14: 10.16.242.33/30 bc 10.16.242.36 | E14: =INDEX(VLSM!$D$5:$D$24,MATCH("L1 PUSAT-DC",VLSM!$B$5:$B$24,0))&INDEX(VLSM!$E$5:$E$24,MATCH("L1 PUSAT-DC",VLSM!$B$5:$B$24,0))&" bc "&INDEX(VLSM!$H$5:$H$24,MATCH("L1 PUSAT-DC",VLSM!$B$5:$B$24,0)) -> 10.16.241.32/30 bc 10.16.241.35 | F14: Network /30 harus kelipatan 4; broadcast = network + 3.
A15: 11 | B15: Soal 3 (VLSM) | C15: L5 PUSAT-BARAT | D15: 10.16.242.37/30 bc 10.16.242.40 | E15: =INDEX(VLSM!$D$5:$D$24,MATCH("L5 PUSAT-BARAT",VLSM!$B$5:$B$24,0))&INDEX(VLSM!$E$5:$E$24,MATCH("L5 PUSAT-BARAT",VLSM!$B$5:$B$24,0))&" bc "&INDEX(VLSM!$H$5:$H$24,MATCH("L5 PUSAT-BARAT",VLSM!$B$5:$B$24,0)) -> 10.16.241.36/30 bc 10.16.241.39 | F15: Sama seperti L1.
A16: 12 | B16: Soal 3 (VLSM) | C16: L2 PUSAT-UTARA | D16: 10.16.242.41/30 bc 10.16.242.44 | E16: =INDEX(VLSM!$D$5:$D$24,MATCH("L2 PUSAT-UTARA",VLSM!$B$5:$B$24,0))&INDEX(VLSM!$E$5:$E$24,MATCH("L2 PUSAT-UTARA",VLSM!$B$5:$B$24,0))&" bc "&INDEX(VLSM!$H$5:$H$24,MATCH("L2 PUSAT-UTARA",VLSM!$B$5:$B$24,0)) -> 10.16.241.40/30 bc 10.16.241.43 | F16: Sama seperti L1.
A17: 13 | B17: Soal 3 (VLSM) | C17: L4 PUSAT-TIMUR | D17: 10.16.242.45/30 bc 10.16.242.48 | E17: =INDEX(VLSM!$D$5:$D$24,MATCH("L4 PUSAT-TIMUR",VLSM!$B$5:$B$24,0))&INDEX(VLSM!$E$5:$E$24,MATCH("L4 PUSAT-TIMUR",VLSM!$B$5:$B$24,0))&" bc "&INDEX(VLSM!$H$5:$H$24,MATCH("L4 PUSAT-TIMUR",VLSM!$B$5:$B$24,0)) -> 10.16.241.44/30 bc 10.16.241.47 | F17: Sama seperti L1.
A18: 14 | B18: Soal 3 (VLSM) | C18: L3 PUSAT-SELATAN | D18: 10.16.242.49/30 bc 10.16.242.52 | E18: =INDEX(VLSM!$D$5:$D$24,MATCH("L3 PUSAT-SELATAN",VLSM!$B$5:$B$24,0))&INDEX(VLSM!$E$5:$E$24,MATCH("L3 PUSAT-SELATAN",VLSM!$B$5:$B$24,0))&" bc "&INDEX(VLSM!$H$5:$H$24,MATCH("L3 PUSAT-SELATAN",VLSM!$B$5:$B$24,0)) -> 10.16.241.48/30 bc 10.16.241.51 | F18: Sama seperti L1.
A19: 15 | B19: Soal 3 (VLSM) | C19: L6 UTARA-PELABUHAN | D19: Tidak ada | E19: =INDEX(VLSM!$D$5:$D$24,MATCH("L6 UTARA-PELABUHAN",VLSM!$B$5:$B$24,0))&INDEX(VLSM!$E$5:$E$24,MATCH("L6 UTARA-PELABUHAN",VLSM!$B$5:$B$24,0))&" bc "&INDEX(VLSM!$H$5:$H$24,MATCH("L6 UTARA-PELABUHAN",VLSM!$B$5:$B$24,0)) -> 10.16.241.52/30 bc 10.16.241.55 | F19: Link R-UTARA – R-PELABUHAN terlewat dari tabel.
